[2025-07-21 18:11:59] [INFO    ] discord.client: logging in using static token
[2025-07-21 18:12:16] [INFO    ] discord.gateway: Shard ID None has connected to Gateway (Session ID: 0705eef9f60ad8e482dd8950ad23c4a4).
[2025-07-21 18:13:28] [ERROR   ] discord.app_commands.tree: Ignoring exception in command 'echo'
Traceback (most recent call last):
  File "/root/Reymond/lib/discord/app_commands/commands.py", line 858, in _do_call
    return await self._callback(interaction, **params)  # type: ignore
           ^^^^^^^^^^^^^^^^^^^^^^^^^^^^^^^^^^^^^^^^^^^
  File "/root/Reymond/main.py", line 63, in echo
    await interaction.response.send_message("Message sent!", ephemeral=True)
  File "/root/Reymond/lib/discord/interactions.py", line 1004, in send_message
    response = await adapter.create_interaction_response(
               ^^^^^^^^^^^^^^^^^^^^^^^^^^^^^^^^^^^^^^^^^^
  File "/root/Reymond/lib/discord/webhook/async_.py", line 224, in request
    raise NotFound(response, data)
discord.errors.NotFound: 404 Not Found (error code: 10062): Unknown interaction

The above exception was the direct cause of the following exception:

Traceback (most recent call last):
  File "/root/Reymond/lib/discord/app_commands/tree.py", line 1310, in _call
    await command._invoke_with_namespace(interaction, namespace)
  File "/root/Reymond/lib/discord/app_commands/commands.py", line 883, in _invoke_with_namespace
    return await self._do_call(interaction, transformed_values)
           ^^^^^^^^^^^^^^^^^^^^^^^^^^^^^^^^^^^^^^^^^^^^^^^^^^^^
  File "/root/Reymond/lib/discord/app_commands/commands.py", line 876, in _do_call
    raise CommandInvokeError(self, e) from e
discord.app_commands.errors.CommandInvokeError: Command 'echo' raised an exception: NotFound: 404 Not Found (error code: 10062): Unknown interaction
[2025-07-21 18:14:29] [ERROR   ] discord.app_commands.tree: Ignoring exception in command 'bank_createcard'
Traceback (most recent call last):
  File "/root/Reymond/lib/discord/app_commands/commands.py", line 858, in _do_call
    return await self._callback(interaction, **params)  # type: ignore
           ^^^^^^^^^^^^^^^^^^^^^^^^^^^^^^^^^^^^^^^^^^^
  File "/root/Reymond/main.py", line 510, in bank_createcard
    await interaction.response.send_message(f"Card created! Your card number: {card_number}", ephemeral=True)
  File "/root/Reymond/lib/discord/interactions.py", line 1004, in send_message
    response = await adapter.create_interaction_response(
               ^^^^^^^^^^^^^^^^^^^^^^^^^^^^^^^^^^^^^^^^^^
  File "/root/Reymond/lib/discord/webhook/async_.py", line 224, in request
    raise NotFound(response, data)
discord.errors.NotFound: 404 Not Found (error code: 10062): Unknown interaction

The above exception was the direct cause of the following exception:

Traceback (most recent call last):
  File "/root/Reymond/lib/discord/app_commands/tree.py", line 1310, in _call
    await command._invoke_with_namespace(interaction, namespace)
  File "/root/Reymond/lib/discord/app_commands/commands.py", line 883, in _invoke_with_namespace
    return await self._do_call(interaction, transformed_values)
           ^^^^^^^^^^^^^^^^^^^^^^^^^^^^^^^^^^^^^^^^^^^^^^^^^^^^
  File "/root/Reymond/lib/discord/app_commands/commands.py", line 876, in _do_call
    raise CommandInvokeError(self, e) from e
discord.app_commands.errors.CommandInvokeError: Command 'bank_createcard' raised an exception: NotFound: 404 Not Found (error code: 10062): Unknown interaction
[2025-07-21 18:19:20] [ERROR   ] discord.app_commands.tree: Ignoring exception in command 'bank_topup'
Traceback (most recent call last):
  File "/root/Reymond/lib/discord/app_commands/commands.py", line 858, in _do_call
    return await self._callback(interaction, **params)  # type: ignore
           ^^^^^^^^^^^^^^^^^^^^^^^^^^^^^^^^^^^^^^^^^^^
  File "/root/Reymond/main.py", line 589, in bank_topup
    await interaction.response.send_message(f"Card {card} topped up by {amount}. New balance: {info['balance']}", ephemeral=True)
  File "/root/Reymond/lib/discord/interactions.py", line 1004, in send_message
    response = await adapter.create_interaction_response(
               ^^^^^^^^^^^^^^^^^^^^^^^^^^^^^^^^^^^^^^^^^^
  File "/root/Reymond/lib/discord/webhook/async_.py", line 224, in request
    raise NotFound(response, data)
discord.errors.NotFound: 404 Not Found (error code: 10062): Unknown interaction

The above exception was the direct cause of the following exception:

Traceback (most recent call last):
  File "/root/Reymond/lib/discord/app_commands/tree.py", line 1310, in _call
    await command._invoke_with_namespace(interaction, namespace)
  File "/root/Reymond/lib/discord/app_commands/commands.py", line 883, in _invoke_with_namespace
    return await self._do_call(interaction, transformed_values)
           ^^^^^^^^^^^^^^^^^^^^^^^^^^^^^^^^^^^^^^^^^^^^^^^^^^^^
  File "/root/Reymond/lib/discord/app_commands/commands.py", line 876, in _do_call
    raise CommandInvokeError(self, e) from e
discord.app_commands.errors.CommandInvokeError: Command 'bank_topup' raised an exception: NotFound: 404 Not Found (error code: 10062): Unknown interaction
[2025-07-21 18:19:34] [ERROR   ] discord.app_commands.tree: Ignoring exception in command 'bank_topup'
Traceback (most recent call last):
  File "/root/Reymond/lib/discord/app_commands/commands.py", line 858, in _do_call
    return await self._callback(interaction, **params)  # type: ignore
           ^^^^^^^^^^^^^^^^^^^^^^^^^^^^^^^^^^^^^^^^^^^
  File "/root/Reymond/main.py", line 589, in bank_topup
    await interaction.response.send_message(f"Card {card} topped up by {amount}. New balance: {info['balance']}", ephemeral=True)
  File "/root/Reymond/lib/discord/interactions.py", line 1004, in send_message
    response = await adapter.create_interaction_response(
               ^^^^^^^^^^^^^^^^^^^^^^^^^^^^^^^^^^^^^^^^^^
  File "/root/Reymond/lib/discord/webhook/async_.py", line 224, in request
    raise NotFound(response, data)
discord.errors.NotFound: 404 Not Found (error code: 10062): Unknown interaction

The above exception was the direct cause of the following exception:

Traceback (most recent call last):
  File "/root/Reymond/lib/discord/app_commands/tree.py", line 1310, in _call
    await command._invoke_with_namespace(interaction, namespace)
  File "/root/Reymond/lib/discord/app_commands/commands.py", line 883, in _invoke_with_namespace
    return await self._do_call(interaction, transformed_values)
           ^^^^^^^^^^^^^^^^^^^^^^^^^^^^^^^^^^^^^^^^^^^^^^^^^^^^
  File "/root/Reymond/lib/discord/app_commands/commands.py", line 876, in _do_call
    raise CommandInvokeError(self, e) from e
discord.app_commands.errors.CommandInvokeError: Command 'bank_topup' raised an exception: NotFound: 404 Not Found (error code: 10062): Unknown interaction
[2025-07-21 18:27:00] [ERROR   ] discord.app_commands.tree: Ignoring exception in command 'bank_transfer'
Traceback (most recent call last):
  File "/root/Reymond/lib/discord/app_commands/commands.py", line 858, in _do_call
    return await self._callback(interaction, **params)  # type: ignore
           ^^^^^^^^^^^^^^^^^^^^^^^^^^^^^^^^^^^^^^^^^^^
  File "/root/Reymond/main.py", line 565, in bank_transfer
    await interaction.response.send_message(
  File "/root/Reymond/lib/discord/interactions.py", line 1004, in send_message
    response = await adapter.create_interaction_response(
               ^^^^^^^^^^^^^^^^^^^^^^^^^^^^^^^^^^^^^^^^^^
  File "/root/Reymond/lib/discord/webhook/async_.py", line 224, in request
    raise NotFound(response, data)
discord.errors.NotFound: 404 Not Found (error code: 10062): Unknown interaction

The above exception was the direct cause of the following exception:

Traceback (most recent call last):
  File "/root/Reymond/lib/discord/app_commands/tree.py", line 1310, in _call
    await command._invoke_with_namespace(interaction, namespace)
  File "/root/Reymond/lib/discord/app_commands/commands.py", line 883, in _invoke_with_namespace
    return await self._do_call(interaction, transformed_values)
           ^^^^^^^^^^^^^^^^^^^^^^^^^^^^^^^^^^^^^^^^^^^^^^^^^^^^
  File "/root/Reymond/lib/discord/app_commands/commands.py", line 876, in _do_call
    raise CommandInvokeError(self, e) from e
discord.app_commands.errors.CommandInvokeError: Command 'bank_transfer' raised an exception: NotFound: 404 Not Found (error code: 10062): Unknown interaction
[2025-07-21 19:12:56] [INFO    ] discord.client: logging in using static token
[2025-07-21 19:13:12] [INFO    ] discord.gateway: Shard ID None has connected to Gateway (Session ID: 7eee2ee5c413e2f4ccbea70463adbce7).
[2025-07-21 19:15:39] [ERROR   ] discord.app_commands.tree: Ignoring exception in command 'echo'
Traceback (most recent call last):
  File "/root/Reymond/lib/discord/app_commands/commands.py", line 858, in _do_call
    return await self._callback(interaction, **params)  # type: ignore
           ^^^^^^^^^^^^^^^^^^^^^^^^^^^^^^^^^^^^^^^^^^^
  File "/root/Reymond/main.py", line 63, in echo
    await interaction.response.send_message("Message sent!", ephemeral=True)
  File "/root/Reymond/lib/discord/interactions.py", line 1004, in send_message
    response = await adapter.create_interaction_response(
               ^^^^^^^^^^^^^^^^^^^^^^^^^^^^^^^^^^^^^^^^^^
  File "/root/Reymond/lib/discord/webhook/async_.py", line 224, in request
    raise NotFound(response, data)
discord.errors.NotFound: 404 Not Found (error code: 10062): Unknown interaction

The above exception was the direct cause of the following exception:

Traceback (most recent call last):
  File "/root/Reymond/lib/discord/app_commands/tree.py", line 1310, in _call
    await command._invoke_with_namespace(interaction, namespace)
  File "/root/Reymond/lib/discord/app_commands/commands.py", line 883, in _invoke_with_namespace
    return await self._do_call(interaction, transformed_values)
           ^^^^^^^^^^^^^^^^^^^^^^^^^^^^^^^^^^^^^^^^^^^^^^^^^^^^
  File "/root/Reymond/lib/discord/app_commands/commands.py", line 876, in _do_call
    raise CommandInvokeError(self, e) from e
discord.app_commands.errors.CommandInvokeError: Command 'echo' raised an exception: NotFound: 404 Not Found (error code: 10062): Unknown interaction
[2025-07-21 19:30:00] [INFO    ] discord.gateway: Shard ID None has successfully RESUMED session 7eee2ee5c413e2f4ccbea70463adbce7.
[2025-07-21 19:54:07] [INFO    ] discord.gateway: Shard ID None has successfully RESUMED session 7eee2ee5c413e2f4ccbea70463adbce7.
[2025-07-21 20:29:05] [INFO    ] discord.gateway: Shard ID None has successfully RESUMED session 7eee2ee5c413e2f4ccbea70463adbce7.
[2025-07-22 00:19:46] [INFO    ] discord.gateway: Shard ID None has successfully RESUMED session 7eee2ee5c413e2f4ccbea70463adbce7.
[2025-07-22 00:44:46] [INFO    ] discord.gateway: Shard ID None has successfully RESUMED session 7eee2ee5c413e2f4ccbea70463adbce7.
[2025-07-22 03:51:46] [INFO    ] discord.gateway: Shard ID None has successfully RESUMED session 7eee2ee5c413e2f4ccbea70463adbce7.
[2025-07-22 07:47:33] [INFO    ] discord.gateway: Shard ID None has successfully RESUMED session 7eee2ee5c413e2f4ccbea70463adbce7.
[2025-07-22 08:22:58] [ERROR   ] discord.app_commands.tree: Ignoring exception in command 'bank_list'
Traceback (most recent call last):
  File "/root/Reymond/lib/discord/app_commands/commands.py", line 858, in _do_call
    return await self._callback(interaction, **params)  # type: ignore
           ^^^^^^^^^^^^^^^^^^^^^^^^^^^^^^^^^^^^^^^^^^^
  File "/root/Reymond/main.py", line 622, in bank_list
    await interaction.response.send_message(msg, ephemeral=True)
  File "/root/Reymond/lib/discord/interactions.py", line 1004, in send_message
    response = await adapter.create_interaction_response(
               ^^^^^^^^^^^^^^^^^^^^^^^^^^^^^^^^^^^^^^^^^^
  File "/root/Reymond/lib/discord/webhook/async_.py", line 224, in request
    raise NotFound(response, data)
discord.errors.NotFound: 404 Not Found (error code: 10062): Unknown interaction

The above exception was the direct cause of the following exception:

Traceback (most recent call last):
  File "/root/Reymond/lib/discord/app_commands/tree.py", line 1310, in _call
    await command._invoke_with_namespace(interaction, namespace)
  File "/root/Reymond/lib/discord/app_commands/commands.py", line 883, in _invoke_with_namespace
    return await self._do_call(interaction, transformed_values)
           ^^^^^^^^^^^^^^^^^^^^^^^^^^^^^^^^^^^^^^^^^^^^^^^^^^^^
  File "/root/Reymond/lib/discord/app_commands/commands.py", line 876, in _do_call
    raise CommandInvokeError(self, e) from e
discord.app_commands.errors.CommandInvokeError: Command 'bank_list' raised an exception: NotFound: 404 Not Found (error code: 10062): Unknown interaction
[2025-07-22 08:23:05] [ERROR   ] discord.app_commands.tree: Ignoring exception in command 'bank_list'
Traceback (most recent call last):
  File "/root/Reymond/lib/discord/app_commands/commands.py", line 858, in _do_call
    return await self._callback(interaction, **params)  # type: ignore
           ^^^^^^^^^^^^^^^^^^^^^^^^^^^^^^^^^^^^^^^^^^^
  File "/root/Reymond/main.py", line 622, in bank_list
    await interaction.response.send_message(msg, ephemeral=True)
  File "/root/Reymond/lib/discord/interactions.py", line 1004, in send_message
    response = await adapter.create_interaction_response(
               ^^^^^^^^^^^^^^^^^^^^^^^^^^^^^^^^^^^^^^^^^^
  File "/root/Reymond/lib/discord/webhook/async_.py", line 224, in request
    raise NotFound(response, data)
discord.errors.NotFound: 404 Not Found (error code: 10062): Unknown interaction

The above exception was the direct cause of the following exception:

Traceback (most recent call last):
  File "/root/Reymond/lib/discord/app_commands/tree.py", line 1310, in _call
    await command._invoke_with_namespace(interaction, namespace)
  File "/root/Reymond/lib/discord/app_commands/commands.py", line 883, in _invoke_with_namespace
    return await self._do_call(interaction, transformed_values)
           ^^^^^^^^^^^^^^^^^^^^^^^^^^^^^^^^^^^^^^^^^^^^^^^^^^^^
  File "/root/Reymond/lib/discord/app_commands/commands.py", line 876, in _do_call
    raise CommandInvokeError(self, e) from e
discord.app_commands.errors.CommandInvokeError: Command 'bank_list' raised an exception: NotFound: 404 Not Found (error code: 10062): Unknown interaction
[2025-07-22 08:37:17] [INFO    ] discord.gateway: Shard ID None has successfully RESUMED session 7eee2ee5c413e2f4ccbea70463adbce7.
[2025-07-22 09:17:53] [INFO    ] discord.gateway: Shard ID None has successfully RESUMED session 7eee2ee5c413e2f4ccbea70463adbce7.
[2025-07-22 13:15:53] [INFO    ] discord.gateway: Shard ID None has successfully RESUMED session 7eee2ee5c413e2f4ccbea70463adbce7.
[2025-07-22 14:44:49] [INFO    ] discord.gateway: Shard ID None has successfully RESUMED session 7eee2ee5c413e2f4ccbea70463adbce7.
[2025-07-22 17:00:46] [INFO    ] discord.gateway: Shard ID None has successfully RESUMED session 7eee2ee5c413e2f4ccbea70463adbce7.
[2025-07-22 18:22:23] [INFO    ] discord.client: logging in using static token
[2025-07-22 18:22:25] [INFO    ] discord.gateway: Shard ID None has connected to Gateway (Session ID: 275805cb755f798efe58b7712dbaafca).
[2025-07-22 20:16:55] [INFO    ] discord.gateway: Shard ID None has successfully RESUMED session 275805cb755f798efe58b7712dbaafca.
[2025-07-22 20:51:01] [INFO    ] discord.gateway: Shard ID None has successfully RESUMED session 275805cb755f798efe58b7712dbaafca.
[2025-07-22 21:20:47] [INFO    ] discord.gateway: Shard ID None has successfully RESUMED session 275805cb755f798efe58b7712dbaafca.
[2025-07-22 22:47:25] [INFO    ] discord.gateway: Shard ID None has successfully RESUMED session 275805cb755f798efe58b7712dbaafca.
[2025-07-23 00:05:48] [INFO    ] discord.gateway: Shard ID None has successfully RESUMED session 275805cb755f798efe58b7712dbaafca.
[2025-07-23 03:54:47] [INFO    ] discord.gateway: Shard ID None has successfully RESUMED session 275805cb755f798efe58b7712dbaafca.
[2025-07-23 05:11:10] [INFO    ] discord.gateway: Shard ID None has successfully RESUMED session 275805cb755f798efe58b7712dbaafca.
[2025-07-23 09:02:05] [INFO    ] discord.gateway: Shard ID None has successfully RESUMED session 275805cb755f798efe58b7712dbaafca.
[2025-07-23 09:17:07] [INFO    ] discord.gateway: Shard ID None has successfully RESUMED session 275805cb755f798efe58b7712dbaafca.
[2025-07-23 10:55:10] [INFO    ] discord.gateway: Shard ID None has successfully RESUMED session 275805cb755f798efe58b7712dbaafca.
[2025-07-23 11:43:46] [INFO    ] discord.gateway: Shard ID None has successfully RESUMED session 275805cb755f798efe58b7712dbaafca.
[2025-07-23 14:34:17] [INFO    ] discord.gateway: Shard ID None has successfully RESUMED session 275805cb755f798efe58b7712dbaafca.
[2025-07-23 15:47:50] [INFO    ] discord.gateway: Shard ID None has successfully RESUMED session 275805cb755f798efe58b7712dbaafca.
Synced 26 command(s)
Loaded ratings for 2 guilds
Logged in as Reymond - 1376901057694928996
------
Bot data saved. Shutting down.
[2025-07-23 16:21:37] [INFO    ] discord.client: logging in using static token
[2025-07-23 16:22:10] [INFO    ] discord.gateway: Shard ID None has connected to Gateway (Session ID: 07f1a51449ca7e3ea34b7b5300c8696a).
[2025-07-23 18:20:19] [INFO    ] discord.gateway: Shard ID None has successfully RESUMED session 07f1a51449ca7e3ea34b7b5300c8696a.
[2025-07-23 19:30:17] [ERROR   ] discord.app_commands.tree: Ignoring exception in command 'bank_createcard'
Traceback (most recent call last):
  File "/root/Reymond/lib/discord/app_commands/commands.py", line 858, in _do_call
    return await self._callback(interaction, **params)  # type: ignore
           ^^^^^^^^^^^^^^^^^^^^^^^^^^^^^^^^^^^^^^^^^^^
  File "/root/Reymond/main.py", line 727, in bank_createcard
    await interaction.response.send_message(embed=embed, ephemeral=True)
  File "/root/Reymond/lib/discord/interactions.py", line 1004, in send_message
    response = await adapter.create_interaction_response(
               ^^^^^^^^^^^^^^^^^^^^^^^^^^^^^^^^^^^^^^^^^^
  File "/root/Reymond/lib/discord/webhook/async_.py", line 224, in request
    raise NotFound(response, data)
discord.errors.NotFound: 404 Not Found (error code: 10062): Unknown interaction

The above exception was the direct cause of the following exception:

Traceback (most recent call last):
  File "/root/Reymond/lib/discord/app_commands/tree.py", line 1310, in _call
    await command._invoke_with_namespace(interaction, namespace)
  File "/root/Reymond/lib/discord/app_commands/commands.py", line 883, in _invoke_with_namespace
    return await self._do_call(interaction, transformed_values)
           ^^^^^^^^^^^^^^^^^^^^^^^^^^^^^^^^^^^^^^^^^^^^^^^^^^^^
  File "/root/Reymond/lib/discord/app_commands/commands.py", line 876, in _do_call
    raise CommandInvokeError(self, e) from e
discord.app_commands.errors.CommandInvokeError: Command 'bank_createcard' raised an exception: NotFound: 404 Not Found (error code: 10062): Unknown interaction
[2025-07-23 19:32:15] [ERROR   ] discord.app_commands.tree: Ignoring exception in command 'bank_list'
Traceback (most recent call last):
  File "/root/Reymond/lib/discord/app_commands/commands.py", line 858, in _do_call
    return await self._callback(interaction, **params)  # type: ignore
           ^^^^^^^^^^^^^^^^^^^^^^^^^^^^^^^^^^^^^^^^^^^
  File "/root/Reymond/main.py", line 1022, in bank_list
    await interaction.response.send_message(embed=embed, ephemeral=True)
  File "/root/Reymond/lib/discord/interactions.py", line 1004, in send_message
    response = await adapter.create_interaction_response(
               ^^^^^^^^^^^^^^^^^^^^^^^^^^^^^^^^^^^^^^^^^^
  File "/root/Reymond/lib/discord/webhook/async_.py", line 224, in request
    raise NotFound(response, data)
discord.errors.NotFound: 404 Not Found (error code: 10062): Unknown interaction

The above exception was the direct cause of the following exception:

Traceback (most recent call last):
  File "/root/Reymond/lib/discord/app_commands/tree.py", line 1310, in _call
    await command._invoke_with_namespace(interaction, namespace)
  File "/root/Reymond/lib/discord/app_commands/commands.py", line 883, in _invoke_with_namespace
    return await self._do_call(interaction, transformed_values)
           ^^^^^^^^^^^^^^^^^^^^^^^^^^^^^^^^^^^^^^^^^^^^^^^^^^^^
  File "/root/Reymond/lib/discord/app_commands/commands.py", line 876, in _do_call
    raise CommandInvokeError(self, e) from e
discord.app_commands.errors.CommandInvokeError: Command 'bank_list' raised an exception: NotFound: 404 Not Found (error code: 10062): Unknown interaction
[2025-07-23 20:09:33] [INFO    ] discord.gateway: Shard ID None has successfully RESUMED session 07f1a51449ca7e3ea34b7b5300c8696a.
[2025-07-23 20:36:07] [ERROR   ] discord.app_commands.tree: Ignoring exception in command 'bank_list'
Traceback (most recent call last):
  File "/root/Reymond/lib/discord/app_commands/commands.py", line 858, in _do_call
    return await self._callback(interaction, **params)  # type: ignore
           ^^^^^^^^^^^^^^^^^^^^^^^^^^^^^^^^^^^^^^^^^^^
  File "/root/Reymond/main.py", line 1022, in bank_list
    await interaction.response.send_message(embed=embed, ephemeral=True)
  File "/root/Reymond/lib/discord/interactions.py", line 1004, in send_message
    response = await adapter.create_interaction_response(
               ^^^^^^^^^^^^^^^^^^^^^^^^^^^^^^^^^^^^^^^^^^
  File "/root/Reymond/lib/discord/webhook/async_.py", line 224, in request
    raise NotFound(response, data)
discord.errors.NotFound: 404 Not Found (error code: 10062): Unknown interaction

The above exception was the direct cause of the following exception:

Traceback (most recent call last):
  File "/root/Reymond/lib/discord/app_commands/tree.py", line 1310, in _call
    await command._invoke_with_namespace(interaction, namespace)
  File "/root/Reymond/lib/discord/app_commands/commands.py", line 883, in _invoke_with_namespace
    return await self._do_call(interaction, transformed_values)
           ^^^^^^^^^^^^^^^^^^^^^^^^^^^^^^^^^^^^^^^^^^^^^^^^^^^^
  File "/root/Reymond/lib/discord/app_commands/commands.py", line 876, in _do_call
    raise CommandInvokeError(self, e) from e
discord.app_commands.errors.CommandInvokeError: Command 'bank_list' raised an exception: NotFound: 404 Not Found (error code: 10062): Unknown interaction
[2025-07-23 20:38:34] [INFO    ] discord.gateway: Shard ID None has successfully RESUMED session 07f1a51449ca7e3ea34b7b5300c8696a.
[2025-07-24 00:05:29] [INFO    ] discord.gateway: Shard ID None has successfully RESUMED session 07f1a51449ca7e3ea34b7b5300c8696a.
[2025-07-24 01:36:00] [INFO    ] discord.gateway: Shard ID None has successfully RESUMED session 07f1a51449ca7e3ea34b7b5300c8696a.
[2025-07-24 02:14:16] [ERROR   ] discord.app_commands.tree: Ignoring exception in command 'bank_createcard'
Traceback (most recent call last):
  File "/root/Reymond/lib/discord/app_commands/commands.py", line 858, in _do_call
    return await self._callback(interaction, **params)  # type: ignore
           ^^^^^^^^^^^^^^^^^^^^^^^^^^^^^^^^^^^^^^^^^^^
  File "/root/Reymond/main.py", line 727, in bank_createcard
    await interaction.response.send_message(embed=embed, ephemeral=True)
  File "/root/Reymond/lib/discord/interactions.py", line 1004, in send_message
    response = await adapter.create_interaction_response(
               ^^^^^^^^^^^^^^^^^^^^^^^^^^^^^^^^^^^^^^^^^^
  File "/root/Reymond/lib/discord/webhook/async_.py", line 224, in request
    raise NotFound(response, data)
discord.errors.NotFound: 404 Not Found (error code: 10062): Unknown interaction

The above exception was the direct cause of the following exception:

Traceback (most recent call last):
  File "/root/Reymond/lib/discord/app_commands/tree.py", line 1310, in _call
    await command._invoke_with_namespace(interaction, namespace)
  File "/root/Reymond/lib/discord/app_commands/commands.py", line 883, in _invoke_with_namespace
    return await self._do_call(interaction, transformed_values)
           ^^^^^^^^^^^^^^^^^^^^^^^^^^^^^^^^^^^^^^^^^^^^^^^^^^^^
  File "/root/Reymond/lib/discord/app_commands/commands.py", line 876, in _do_call
    raise CommandInvokeError(self, e) from e
discord.app_commands.errors.CommandInvokeError: Command 'bank_createcard' raised an exception: NotFound: 404 Not Found (error code: 10062): Unknown interaction
[2025-07-24 02:58:14] [INFO    ] discord.gateway: Shard ID None has successfully RESUMED session 07f1a51449ca7e3ea34b7b5300c8696a.
[2025-07-24 03:18:07] [INFO    ] discord.gateway: Shard ID None has successfully RESUMED session 07f1a51449ca7e3ea34b7b5300c8696a.
[2025-07-24 05:56:24] [INFO    ] discord.gateway: Shard ID None has successfully RESUMED session 07f1a51449ca7e3ea34b7b5300c8696a.
[2025-07-24 08:04:49] [INFO    ] discord.gateway: Shard ID None has successfully RESUMED session 07f1a51449ca7e3ea34b7b5300c8696a.
[2025-07-24 10:55:13] [INFO    ] discord.gateway: Shard ID None has successfully RESUMED session 07f1a51449ca7e3ea34b7b5300c8696a.
[2025-07-24 12:30:51] [INFO    ] discord.gateway: Shard ID None has successfully RESUMED session 07f1a51449ca7e3ea34b7b5300c8696a.
[2025-07-24 12:52:50] [INFO    ] discord.gateway: Shard ID None has successfully RESUMED session 07f1a51449ca7e3ea34b7b5300c8696a.
[2025-07-24 14:55:21] [INFO    ] discord.gateway: Shard ID None has successfully RESUMED session 07f1a51449ca7e3ea34b7b5300c8696a.
[2025-07-24 16:08:12] [INFO    ] discord.gateway: Shard ID None has successfully RESUMED session 07f1a51449ca7e3ea34b7b5300c8696a.
[2025-07-24 16:25:42] [ERROR   ] discord.client: Attempting a reconnect in 0.52s
Traceback (most recent call last):
  File "/usr/lib/python3.12/asyncio/tasks.py", line 520, in wait_for
    return await fut
           ^^^^^^^^^
  File "/root/Reymond/lib/discord/gateway.py", line 375, in from_client
    socket = await client.http.ws_connect(str(url))
             ^^^^^^^^^^^^^^^^^^^^^^^^^^^^^^^^^^^^^^
  File "/root/Reymond/lib/discord/http.py", line 554, in ws_connect
    return await self.__session.ws_connect(url, **kwargs)
           ^^^^^^^^^^^^^^^^^^^^^^^^^^^^^^^^^^^^^^^^^^^^^^
  File "/root/Reymond/lib/aiohttp/client.py", line 1048, in _ws_connect
    resp = await self.request(
           ^^^^^^^^^^^^^^^^^^^
  File "/root/Reymond/lib/aiohttp/client.py", line 760, in _request
    resp = await handler(req)
           ^^^^^^^^^^^^^^^^^^
  File "/root/Reymond/lib/aiohttp/client.py", line 715, in _connect_and_send_request
    conn = await self._connector.connect(
           ^^^^^^^^^^^^^^^^^^^^^^^^^^^^^^
  File "/root/Reymond/lib/aiohttp/connector.py", line 561, in connect
    proto = await self._create_connection(req, traces, timeout)
            ^^^^^^^^^^^^^^^^^^^^^^^^^^^^^^^^^^^^^^^^^^^^^^^^^^^
  File "/root/Reymond/lib/aiohttp/connector.py", line 1074, in _create_connection
    _, proto = await self._create_direct_connection(req, traces, timeout)
               ^^^^^^^^^^^^^^^^^^^^^^^^^^^^^^^^^^^^^^^^^^^^^^^^^^^^^^^^^^
  File "/root/Reymond/lib/aiohttp/connector.py", line 1394, in _create_direct_connection
    transp, proto = await self._wrap_create_connection(
                    ^^^^^^^^^^^^^^^^^^^^^^^^^^^^^^^^^^^
  File "/root/Reymond/lib/aiohttp/connector.py", line 1141, in _wrap_create_connection
    return await self._loop.create_connection(*args, **kwargs, sock=sock)
           ^^^^^^^^^^^^^^^^^^^^^^^^^^^^^^^^^^^^^^^^^^^^^^^^^^^^^^^^^^^^^^
  File "/usr/lib/python3.12/asyncio/base_events.py", line 1149, in create_connection
    transport, protocol = await self._create_connection_transport(
                          ^^^^^^^^^^^^^^^^^^^^^^^^^^^^^^^^^^^^^^^^
  File "/usr/lib/python3.12/asyncio/base_events.py", line 1182, in _create_connection_transport
    await waiter
asyncio.exceptions.CancelledError

The above exception was the direct cause of the following exception:

Traceback (most recent call last):
  File "/root/Reymond/lib/discord/client.py", line 701, in connect
    self.ws = await asyncio.wait_for(coro, timeout=60.0)
              ^^^^^^^^^^^^^^^^^^^^^^^^^^^^^^^^^^^^^^^^^^
  File "/usr/lib/python3.12/asyncio/tasks.py", line 519, in wait_for
    async with timeouts.timeout(timeout):
  File "/usr/lib/python3.12/asyncio/timeouts.py", line 115, in __aexit__
    raise TimeoutError from exc_val
TimeoutError
[2025-07-24 16:26:42] [ERROR   ] discord.client: Attempting a reconnect in 1.77s
Traceback (most recent call last):
  File "/usr/lib/python3.12/asyncio/tasks.py", line 520, in wait_for
    return await fut
           ^^^^^^^^^
  File "/root/Reymond/lib/discord/gateway.py", line 375, in from_client
    socket = await client.http.ws_connect(str(url))
             ^^^^^^^^^^^^^^^^^^^^^^^^^^^^^^^^^^^^^^
  File "/root/Reymond/lib/discord/http.py", line 554, in ws_connect
    return await self.__session.ws_connect(url, **kwargs)
           ^^^^^^^^^^^^^^^^^^^^^^^^^^^^^^^^^^^^^^^^^^^^^^
  File "/root/Reymond/lib/aiohttp/client.py", line 1048, in _ws_connect
    resp = await self.request(
           ^^^^^^^^^^^^^^^^^^^
  File "/root/Reymond/lib/aiohttp/client.py", line 760, in _request
    resp = await handler(req)
           ^^^^^^^^^^^^^^^^^^
  File "/root/Reymond/lib/aiohttp/client.py", line 715, in _connect_and_send_request
    conn = await self._connector.connect(
           ^^^^^^^^^^^^^^^^^^^^^^^^^^^^^^
  File "/root/Reymond/lib/aiohttp/connector.py", line 561, in connect
    proto = await self._create_connection(req, traces, timeout)
            ^^^^^^^^^^^^^^^^^^^^^^^^^^^^^^^^^^^^^^^^^^^^^^^^^^^
  File "/root/Reymond/lib/aiohttp/connector.py", line 1074, in _create_connection
    _, proto = await self._create_direct_connection(req, traces, timeout)
               ^^^^^^^^^^^^^^^^^^^^^^^^^^^^^^^^^^^^^^^^^^^^^^^^^^^^^^^^^^
  File "/root/Reymond/lib/aiohttp/connector.py", line 1394, in _create_direct_connection
    transp, proto = await self._wrap_create_connection(
                    ^^^^^^^^^^^^^^^^^^^^^^^^^^^^^^^^^^^
  File "/root/Reymond/lib/aiohttp/connector.py", line 1141, in _wrap_create_connection
    return await self._loop.create_connection(*args, **kwargs, sock=sock)
           ^^^^^^^^^^^^^^^^^^^^^^^^^^^^^^^^^^^^^^^^^^^^^^^^^^^^^^^^^^^^^^
  File "/usr/lib/python3.12/asyncio/base_events.py", line 1149, in create_connection
    transport, protocol = await self._create_connection_transport(
                          ^^^^^^^^^^^^^^^^^^^^^^^^^^^^^^^^^^^^^^^^
  File "/usr/lib/python3.12/asyncio/base_events.py", line 1182, in _create_connection_transport
    await waiter
asyncio.exceptions.CancelledError

The above exception was the direct cause of the following exception:

Traceback (most recent call last):
  File "/root/Reymond/lib/discord/client.py", line 701, in connect
    self.ws = await asyncio.wait_for(coro, timeout=60.0)
              ^^^^^^^^^^^^^^^^^^^^^^^^^^^^^^^^^^^^^^^^^^
  File "/usr/lib/python3.12/asyncio/tasks.py", line 519, in wait_for
    async with timeouts.timeout(timeout):
  File "/usr/lib/python3.12/asyncio/timeouts.py", line 115, in __aexit__
    raise TimeoutError from exc_val
TimeoutError
[2025-07-24 16:27:44] [ERROR   ] discord.client: Attempting a reconnect in 0.36s
Traceback (most recent call last):
  File "/usr/lib/python3.12/asyncio/tasks.py", line 520, in wait_for
    return await fut
           ^^^^^^^^^
  File "/root/Reymond/lib/discord/gateway.py", line 375, in from_client
    socket = await client.http.ws_connect(str(url))
             ^^^^^^^^^^^^^^^^^^^^^^^^^^^^^^^^^^^^^^
  File "/root/Reymond/lib/discord/http.py", line 554, in ws_connect
    return await self.__session.ws_connect(url, **kwargs)
           ^^^^^^^^^^^^^^^^^^^^^^^^^^^^^^^^^^^^^^^^^^^^^^
  File "/root/Reymond/lib/aiohttp/client.py", line 1048, in _ws_connect
    resp = await self.request(
           ^^^^^^^^^^^^^^^^^^^
  File "/root/Reymond/lib/aiohttp/client.py", line 760, in _request
    resp = await handler(req)
           ^^^^^^^^^^^^^^^^^^
  File "/root/Reymond/lib/aiohttp/client.py", line 715, in _connect_and_send_request
    conn = await self._connector.connect(
           ^^^^^^^^^^^^^^^^^^^^^^^^^^^^^^
  File "/root/Reymond/lib/aiohttp/connector.py", line 561, in connect
    proto = await self._create_connection(req, traces, timeout)
            ^^^^^^^^^^^^^^^^^^^^^^^^^^^^^^^^^^^^^^^^^^^^^^^^^^^
  File "/root/Reymond/lib/aiohttp/connector.py", line 1074, in _create_connection
    _, proto = await self._create_direct_connection(req, traces, timeout)
               ^^^^^^^^^^^^^^^^^^^^^^^^^^^^^^^^^^^^^^^^^^^^^^^^^^^^^^^^^^
  File "/root/Reymond/lib/aiohttp/connector.py", line 1394, in _create_direct_connection
    transp, proto = await self._wrap_create_connection(
                    ^^^^^^^^^^^^^^^^^^^^^^^^^^^^^^^^^^^
  File "/root/Reymond/lib/aiohttp/connector.py", line 1141, in _wrap_create_connection
    return await self._loop.create_connection(*args, **kwargs, sock=sock)
           ^^^^^^^^^^^^^^^^^^^^^^^^^^^^^^^^^^^^^^^^^^^^^^^^^^^^^^^^^^^^^^
  File "/usr/lib/python3.12/asyncio/base_events.py", line 1149, in create_connection
    transport, protocol = await self._create_connection_transport(
                          ^^^^^^^^^^^^^^^^^^^^^^^^^^^^^^^^^^^^^^^^
  File "/usr/lib/python3.12/asyncio/base_events.py", line 1182, in _create_connection_transport
    await waiter
asyncio.exceptions.CancelledError

The above exception was the direct cause of the following exception:

Traceback (most recent call last):
  File "/root/Reymond/lib/discord/client.py", line 701, in connect
    self.ws = await asyncio.wait_for(coro, timeout=60.0)
              ^^^^^^^^^^^^^^^^^^^^^^^^^^^^^^^^^^^^^^^^^^
  File "/usr/lib/python3.12/asyncio/tasks.py", line 519, in wait_for
    async with timeouts.timeout(timeout):
  File "/usr/lib/python3.12/asyncio/timeouts.py", line 115, in __aexit__
    raise TimeoutError from exc_val
TimeoutError
[2025-07-24 16:28:44] [ERROR   ] discord.client: Attempting a reconnect in 12.62s
Traceback (most recent call last):
  File "/usr/lib/python3.12/asyncio/tasks.py", line 520, in wait_for
    return await fut
           ^^^^^^^^^
  File "/root/Reymond/lib/discord/gateway.py", line 375, in from_client
    socket = await client.http.ws_connect(str(url))
             ^^^^^^^^^^^^^^^^^^^^^^^^^^^^^^^^^^^^^^
  File "/root/Reymond/lib/discord/http.py", line 554, in ws_connect
    return await self.__session.ws_connect(url, **kwargs)
           ^^^^^^^^^^^^^^^^^^^^^^^^^^^^^^^^^^^^^^^^^^^^^^
  File "/root/Reymond/lib/aiohttp/client.py", line 1048, in _ws_connect
    resp = await self.request(
           ^^^^^^^^^^^^^^^^^^^
  File "/root/Reymond/lib/aiohttp/client.py", line 760, in _request
    resp = await handler(req)
           ^^^^^^^^^^^^^^^^^^
  File "/root/Reymond/lib/aiohttp/client.py", line 715, in _connect_and_send_request
    conn = await self._connector.connect(
           ^^^^^^^^^^^^^^^^^^^^^^^^^^^^^^
  File "/root/Reymond/lib/aiohttp/connector.py", line 561, in connect
    proto = await self._create_connection(req, traces, timeout)
            ^^^^^^^^^^^^^^^^^^^^^^^^^^^^^^^^^^^^^^^^^^^^^^^^^^^
  File "/root/Reymond/lib/aiohttp/connector.py", line 1074, in _create_connection
    _, proto = await self._create_direct_connection(req, traces, timeout)
               ^^^^^^^^^^^^^^^^^^^^^^^^^^^^^^^^^^^^^^^^^^^^^^^^^^^^^^^^^^
  File "/root/Reymond/lib/aiohttp/connector.py", line 1394, in _create_direct_connection
    transp, proto = await self._wrap_create_connection(
                    ^^^^^^^^^^^^^^^^^^^^^^^^^^^^^^^^^^^
  File "/root/Reymond/lib/aiohttp/connector.py", line 1141, in _wrap_create_connection
    return await self._loop.create_connection(*args, **kwargs, sock=sock)
           ^^^^^^^^^^^^^^^^^^^^^^^^^^^^^^^^^^^^^^^^^^^^^^^^^^^^^^^^^^^^^^
  File "/usr/lib/python3.12/asyncio/base_events.py", line 1149, in create_connection
    transport, protocol = await self._create_connection_transport(
                          ^^^^^^^^^^^^^^^^^^^^^^^^^^^^^^^^^^^^^^^^
  File "/usr/lib/python3.12/asyncio/base_events.py", line 1182, in _create_connection_transport
    await waiter
asyncio.exceptions.CancelledError

The above exception was the direct cause of the following exception:

Traceback (most recent call last):
  File "/root/Reymond/lib/discord/client.py", line 701, in connect
    self.ws = await asyncio.wait_for(coro, timeout=60.0)
              ^^^^^^^^^^^^^^^^^^^^^^^^^^^^^^^^^^^^^^^^^^
  File "/usr/lib/python3.12/asyncio/tasks.py", line 519, in wait_for
    async with timeouts.timeout(timeout):
  File "/usr/lib/python3.12/asyncio/timeouts.py", line 115, in __aexit__
    raise TimeoutError from exc_val
TimeoutError
[2025-07-24 16:29:57] [ERROR   ] discord.client: Attempting a reconnect in 19.92s
Traceback (most recent call last):
  File "/usr/lib/python3.12/asyncio/tasks.py", line 520, in wait_for
    return await fut
           ^^^^^^^^^
  File "/root/Reymond/lib/discord/gateway.py", line 375, in from_client
    socket = await client.http.ws_connect(str(url))
             ^^^^^^^^^^^^^^^^^^^^^^^^^^^^^^^^^^^^^^
  File "/root/Reymond/lib/discord/http.py", line 554, in ws_connect
    return await self.__session.ws_connect(url, **kwargs)
           ^^^^^^^^^^^^^^^^^^^^^^^^^^^^^^^^^^^^^^^^^^^^^^
  File "/root/Reymond/lib/aiohttp/client.py", line 1048, in _ws_connect
    resp = await self.request(
           ^^^^^^^^^^^^^^^^^^^
  File "/root/Reymond/lib/aiohttp/client.py", line 760, in _request
    resp = await handler(req)
           ^^^^^^^^^^^^^^^^^^
  File "/root/Reymond/lib/aiohttp/client.py", line 715, in _connect_and_send_request
    conn = await self._connector.connect(
           ^^^^^^^^^^^^^^^^^^^^^^^^^^^^^^
  File "/root/Reymond/lib/aiohttp/connector.py", line 561, in connect
    proto = await self._create_connection(req, traces, timeout)
            ^^^^^^^^^^^^^^^^^^^^^^^^^^^^^^^^^^^^^^^^^^^^^^^^^^^
  File "/root/Reymond/lib/aiohttp/connector.py", line 1074, in _create_connection
    _, proto = await self._create_direct_connection(req, traces, timeout)
               ^^^^^^^^^^^^^^^^^^^^^^^^^^^^^^^^^^^^^^^^^^^^^^^^^^^^^^^^^^
  File "/root/Reymond/lib/aiohttp/connector.py", line 1394, in _create_direct_connection
    transp, proto = await self._wrap_create_connection(
                    ^^^^^^^^^^^^^^^^^^^^^^^^^^^^^^^^^^^
  File "/root/Reymond/lib/aiohttp/connector.py", line 1141, in _wrap_create_connection
    return await self._loop.create_connection(*args, **kwargs, sock=sock)
           ^^^^^^^^^^^^^^^^^^^^^^^^^^^^^^^^^^^^^^^^^^^^^^^^^^^^^^^^^^^^^^
  File "/usr/lib/python3.12/asyncio/base_events.py", line 1149, in create_connection
    transport, protocol = await self._create_connection_transport(
                          ^^^^^^^^^^^^^^^^^^^^^^^^^^^^^^^^^^^^^^^^
  File "/usr/lib/python3.12/asyncio/base_events.py", line 1182, in _create_connection_transport
    await waiter
asyncio.exceptions.CancelledError

The above exception was the direct cause of the following exception:

Traceback (most recent call last):
  File "/root/Reymond/lib/discord/client.py", line 701, in connect
    self.ws = await asyncio.wait_for(coro, timeout=60.0)
              ^^^^^^^^^^^^^^^^^^^^^^^^^^^^^^^^^^^^^^^^^^
  File "/usr/lib/python3.12/asyncio/tasks.py", line 519, in wait_for
    async with timeouts.timeout(timeout):
  File "/usr/lib/python3.12/asyncio/timeouts.py", line 115, in __aexit__
    raise TimeoutError from exc_val
TimeoutError
[2025-07-24 16:31:17] [ERROR   ] discord.client: Attempting a reconnect in 5.68s
Traceback (most recent call last):
  File "/usr/lib/python3.12/asyncio/tasks.py", line 520, in wait_for
    return await fut
           ^^^^^^^^^
  File "/root/Reymond/lib/discord/gateway.py", line 375, in from_client
    socket = await client.http.ws_connect(str(url))
             ^^^^^^^^^^^^^^^^^^^^^^^^^^^^^^^^^^^^^^
  File "/root/Reymond/lib/discord/http.py", line 554, in ws_connect
    return await self.__session.ws_connect(url, **kwargs)
           ^^^^^^^^^^^^^^^^^^^^^^^^^^^^^^^^^^^^^^^^^^^^^^
  File "/root/Reymond/lib/aiohttp/client.py", line 1048, in _ws_connect
    resp = await self.request(
           ^^^^^^^^^^^^^^^^^^^
  File "/root/Reymond/lib/aiohttp/client.py", line 760, in _request
    resp = await handler(req)
           ^^^^^^^^^^^^^^^^^^
  File "/root/Reymond/lib/aiohttp/client.py", line 715, in _connect_and_send_request
    conn = await self._connector.connect(
           ^^^^^^^^^^^^^^^^^^^^^^^^^^^^^^
  File "/root/Reymond/lib/aiohttp/connector.py", line 561, in connect
    proto = await self._create_connection(req, traces, timeout)
            ^^^^^^^^^^^^^^^^^^^^^^^^^^^^^^^^^^^^^^^^^^^^^^^^^^^
  File "/root/Reymond/lib/aiohttp/connector.py", line 1074, in _create_connection
    _, proto = await self._create_direct_connection(req, traces, timeout)
               ^^^^^^^^^^^^^^^^^^^^^^^^^^^^^^^^^^^^^^^^^^^^^^^^^^^^^^^^^^
  File "/root/Reymond/lib/aiohttp/connector.py", line 1394, in _create_direct_connection
    transp, proto = await self._wrap_create_connection(
                    ^^^^^^^^^^^^^^^^^^^^^^^^^^^^^^^^^^^
  File "/root/Reymond/lib/aiohttp/connector.py", line 1141, in _wrap_create_connection
    return await self._loop.create_connection(*args, **kwargs, sock=sock)
           ^^^^^^^^^^^^^^^^^^^^^^^^^^^^^^^^^^^^^^^^^^^^^^^^^^^^^^^^^^^^^^
  File "/usr/lib/python3.12/asyncio/base_events.py", line 1149, in create_connection
    transport, protocol = await self._create_connection_transport(
                          ^^^^^^^^^^^^^^^^^^^^^^^^^^^^^^^^^^^^^^^^
  File "/usr/lib/python3.12/asyncio/base_events.py", line 1182, in _create_connection_transport
    await waiter
asyncio.exceptions.CancelledError

The above exception was the direct cause of the following exception:

Traceback (most recent call last):
  File "/root/Reymond/lib/discord/client.py", line 701, in connect
    self.ws = await asyncio.wait_for(coro, timeout=60.0)
              ^^^^^^^^^^^^^^^^^^^^^^^^^^^^^^^^^^^^^^^^^^
  File "/usr/lib/python3.12/asyncio/tasks.py", line 519, in wait_for
    async with timeouts.timeout(timeout):
  File "/usr/lib/python3.12/asyncio/timeouts.py", line 115, in __aexit__
    raise TimeoutError from exc_val
TimeoutError
[2025-07-24 16:32:23] [ERROR   ] discord.client: Attempting a reconnect in 70.91s
Traceback (most recent call last):
  File "/usr/lib/python3.12/asyncio/tasks.py", line 520, in wait_for
    return await fut
           ^^^^^^^^^
  File "/root/Reymond/lib/discord/gateway.py", line 375, in from_client
    socket = await client.http.ws_connect(str(url))
             ^^^^^^^^^^^^^^^^^^^^^^^^^^^^^^^^^^^^^^
  File "/root/Reymond/lib/discord/http.py", line 554, in ws_connect
    return await self.__session.ws_connect(url, **kwargs)
           ^^^^^^^^^^^^^^^^^^^^^^^^^^^^^^^^^^^^^^^^^^^^^^
  File "/root/Reymond/lib/aiohttp/client.py", line 1048, in _ws_connect
    resp = await self.request(
           ^^^^^^^^^^^^^^^^^^^
  File "/root/Reymond/lib/aiohttp/client.py", line 760, in _request
    resp = await handler(req)
           ^^^^^^^^^^^^^^^^^^
  File "/root/Reymond/lib/aiohttp/client.py", line 715, in _connect_and_send_request
    conn = await self._connector.connect(
           ^^^^^^^^^^^^^^^^^^^^^^^^^^^^^^
  File "/root/Reymond/lib/aiohttp/connector.py", line 561, in connect
    proto = await self._create_connection(req, traces, timeout)
            ^^^^^^^^^^^^^^^^^^^^^^^^^^^^^^^^^^^^^^^^^^^^^^^^^^^
  File "/root/Reymond/lib/aiohttp/connector.py", line 1074, in _create_connection
    _, proto = await self._create_direct_connection(req, traces, timeout)
               ^^^^^^^^^^^^^^^^^^^^^^^^^^^^^^^^^^^^^^^^^^^^^^^^^^^^^^^^^^
  File "/root/Reymond/lib/aiohttp/connector.py", line 1394, in _create_direct_connection
    transp, proto = await self._wrap_create_connection(
                    ^^^^^^^^^^^^^^^^^^^^^^^^^^^^^^^^^^^
  File "/root/Reymond/lib/aiohttp/connector.py", line 1141, in _wrap_create_connection
    return await self._loop.create_connection(*args, **kwargs, sock=sock)
           ^^^^^^^^^^^^^^^^^^^^^^^^^^^^^^^^^^^^^^^^^^^^^^^^^^^^^^^^^^^^^^
  File "/usr/lib/python3.12/asyncio/base_events.py", line 1149, in create_connection
    transport, protocol = await self._create_connection_transport(
                          ^^^^^^^^^^^^^^^^^^^^^^^^^^^^^^^^^^^^^^^^
  File "/usr/lib/python3.12/asyncio/base_events.py", line 1182, in _create_connection_transport
    await waiter
asyncio.exceptions.CancelledError

The above exception was the direct cause of the following exception:

Traceback (most recent call last):
  File "/root/Reymond/lib/discord/client.py", line 701, in connect
    self.ws = await asyncio.wait_for(coro, timeout=60.0)
              ^^^^^^^^^^^^^^^^^^^^^^^^^^^^^^^^^^^^^^^^^^
  File "/usr/lib/python3.12/asyncio/tasks.py", line 519, in wait_for
    async with timeouts.timeout(timeout):
  File "/usr/lib/python3.12/asyncio/timeouts.py", line 115, in __aexit__
    raise TimeoutError from exc_val
TimeoutError
[2025-07-24 16:34:34] [ERROR   ] discord.client: Attempting a reconnect in 166.31s
Traceback (most recent call last):
  File "/usr/lib/python3.12/asyncio/tasks.py", line 520, in wait_for
    return await fut
           ^^^^^^^^^
  File "/root/Reymond/lib/discord/gateway.py", line 375, in from_client
    socket = await client.http.ws_connect(str(url))
             ^^^^^^^^^^^^^^^^^^^^^^^^^^^^^^^^^^^^^^
  File "/root/Reymond/lib/discord/http.py", line 554, in ws_connect
    return await self.__session.ws_connect(url, **kwargs)
           ^^^^^^^^^^^^^^^^^^^^^^^^^^^^^^^^^^^^^^^^^^^^^^
  File "/root/Reymond/lib/aiohttp/client.py", line 1048, in _ws_connect
    resp = await self.request(
           ^^^^^^^^^^^^^^^^^^^
  File "/root/Reymond/lib/aiohttp/client.py", line 760, in _request
    resp = await handler(req)
           ^^^^^^^^^^^^^^^^^^
  File "/root/Reymond/lib/aiohttp/client.py", line 715, in _connect_and_send_request
    conn = await self._connector.connect(
           ^^^^^^^^^^^^^^^^^^^^^^^^^^^^^^
  File "/root/Reymond/lib/aiohttp/connector.py", line 561, in connect
    proto = await self._create_connection(req, traces, timeout)
            ^^^^^^^^^^^^^^^^^^^^^^^^^^^^^^^^^^^^^^^^^^^^^^^^^^^
  File "/root/Reymond/lib/aiohttp/connector.py", line 1074, in _create_connection
    _, proto = await self._create_direct_connection(req, traces, timeout)
               ^^^^^^^^^^^^^^^^^^^^^^^^^^^^^^^^^^^^^^^^^^^^^^^^^^^^^^^^^^
  File "/root/Reymond/lib/aiohttp/connector.py", line 1394, in _create_direct_connection
    transp, proto = await self._wrap_create_connection(
                    ^^^^^^^^^^^^^^^^^^^^^^^^^^^^^^^^^^^
  File "/root/Reymond/lib/aiohttp/connector.py", line 1141, in _wrap_create_connection
    return await self._loop.create_connection(*args, **kwargs, sock=sock)
           ^^^^^^^^^^^^^^^^^^^^^^^^^^^^^^^^^^^^^^^^^^^^^^^^^^^^^^^^^^^^^^
  File "/usr/lib/python3.12/asyncio/base_events.py", line 1149, in create_connection
    transport, protocol = await self._create_connection_transport(
                          ^^^^^^^^^^^^^^^^^^^^^^^^^^^^^^^^^^^^^^^^
  File "/usr/lib/python3.12/asyncio/base_events.py", line 1182, in _create_connection_transport
    await waiter
asyncio.exceptions.CancelledError

The above exception was the direct cause of the following exception:

Traceback (most recent call last):
  File "/root/Reymond/lib/discord/client.py", line 701, in connect
    self.ws = await asyncio.wait_for(coro, timeout=60.0)
              ^^^^^^^^^^^^^^^^^^^^^^^^^^^^^^^^^^^^^^^^^^
  File "/usr/lib/python3.12/asyncio/tasks.py", line 519, in wait_for
    async with timeouts.timeout(timeout):
  File "/usr/lib/python3.12/asyncio/timeouts.py", line 115, in __aexit__
    raise TimeoutError from exc_val
TimeoutError
[2025-07-24 16:37:58] [INFO    ] discord.gateway: Shard ID None session has been invalidated.
[2025-07-24 16:38:04] [INFO    ] discord.gateway: Shard ID None has connected to Gateway (Session ID: 83fc1c83f8e9834754e32343258fe4d7).
[2025-07-24 17:21:34] [INFO    ] discord.gateway: Shard ID None has successfully RESUMED session 83fc1c83f8e9834754e32343258fe4d7.
[2025-07-24 19:05:42] [INFO    ] discord.gateway: Shard ID None has successfully RESUMED session 83fc1c83f8e9834754e32343258fe4d7.
[2025-07-24 19:55:13] [INFO    ] discord.gateway: Shard ID None has successfully RESUMED session 83fc1c83f8e9834754e32343258fe4d7.
[2025-07-24 20:12:52] [INFO    ] discord.gateway: Shard ID None has successfully RESUMED session 83fc1c83f8e9834754e32343258fe4d7.
[2025-07-24 20:34:25] [INFO    ] discord.gateway: Shard ID None has successfully RESUMED session 83fc1c83f8e9834754e32343258fe4d7.
[2025-07-24 21:49:57] [INFO    ] discord.gateway: Shard ID None has successfully RESUMED session 83fc1c83f8e9834754e32343258fe4d7.
[2025-07-24 22:20:39] [ERROR   ] discord.client: Attempting a reconnect in 1.39s
Traceback (most recent call last):
  File "/usr/lib/python3.12/asyncio/tasks.py", line 520, in wait_for
    return await fut
           ^^^^^^^^^
  File "/root/Reymond/lib/discord/gateway.py", line 375, in from_client
    socket = await client.http.ws_connect(str(url))
             ^^^^^^^^^^^^^^^^^^^^^^^^^^^^^^^^^^^^^^
  File "/root/Reymond/lib/discord/http.py", line 554, in ws_connect
    return await self.__session.ws_connect(url, **kwargs)
           ^^^^^^^^^^^^^^^^^^^^^^^^^^^^^^^^^^^^^^^^^^^^^^
  File "/root/Reymond/lib/aiohttp/client.py", line 1048, in _ws_connect
    resp = await self.request(
           ^^^^^^^^^^^^^^^^^^^
  File "/root/Reymond/lib/aiohttp/client.py", line 760, in _request
    resp = await handler(req)
           ^^^^^^^^^^^^^^^^^^
  File "/root/Reymond/lib/aiohttp/client.py", line 715, in _connect_and_send_request
    conn = await self._connector.connect(
           ^^^^^^^^^^^^^^^^^^^^^^^^^^^^^^
  File "/root/Reymond/lib/aiohttp/connector.py", line 561, in connect
    proto = await self._create_connection(req, traces, timeout)
            ^^^^^^^^^^^^^^^^^^^^^^^^^^^^^^^^^^^^^^^^^^^^^^^^^^^
  File "/root/Reymond/lib/aiohttp/connector.py", line 1074, in _create_connection
    _, proto = await self._create_direct_connection(req, traces, timeout)
               ^^^^^^^^^^^^^^^^^^^^^^^^^^^^^^^^^^^^^^^^^^^^^^^^^^^^^^^^^^
  File "/root/Reymond/lib/aiohttp/connector.py", line 1394, in _create_direct_connection
    transp, proto = await self._wrap_create_connection(
                    ^^^^^^^^^^^^^^^^^^^^^^^^^^^^^^^^^^^
  File "/root/Reymond/lib/aiohttp/connector.py", line 1141, in _wrap_create_connection
    return await self._loop.create_connection(*args, **kwargs, sock=sock)
           ^^^^^^^^^^^^^^^^^^^^^^^^^^^^^^^^^^^^^^^^^^^^^^^^^^^^^^^^^^^^^^
  File "/usr/lib/python3.12/asyncio/base_events.py", line 1149, in create_connection
    transport, protocol = await self._create_connection_transport(
                          ^^^^^^^^^^^^^^^^^^^^^^^^^^^^^^^^^^^^^^^^
  File "/usr/lib/python3.12/asyncio/base_events.py", line 1182, in _create_connection_transport
    await waiter
asyncio.exceptions.CancelledError

The above exception was the direct cause of the following exception:

Traceback (most recent call last):
  File "/root/Reymond/lib/discord/client.py", line 701, in connect
    self.ws = await asyncio.wait_for(coro, timeout=60.0)
              ^^^^^^^^^^^^^^^^^^^^^^^^^^^^^^^^^^^^^^^^^^
  File "/usr/lib/python3.12/asyncio/tasks.py", line 519, in wait_for
    async with timeouts.timeout(timeout):
  File "/usr/lib/python3.12/asyncio/timeouts.py", line 115, in __aexit__
    raise TimeoutError from exc_val
TimeoutError
[2025-07-24 22:21:41] [ERROR   ] discord.client: Attempting a reconnect in 1.44s
Traceback (most recent call last):
  File "/usr/lib/python3.12/asyncio/tasks.py", line 520, in wait_for
    return await fut
           ^^^^^^^^^
  File "/root/Reymond/lib/discord/gateway.py", line 375, in from_client
    socket = await client.http.ws_connect(str(url))
             ^^^^^^^^^^^^^^^^^^^^^^^^^^^^^^^^^^^^^^
  File "/root/Reymond/lib/discord/http.py", line 554, in ws_connect
    return await self.__session.ws_connect(url, **kwargs)
           ^^^^^^^^^^^^^^^^^^^^^^^^^^^^^^^^^^^^^^^^^^^^^^
  File "/root/Reymond/lib/aiohttp/client.py", line 1048, in _ws_connect
    resp = await self.request(
           ^^^^^^^^^^^^^^^^^^^
  File "/root/Reymond/lib/aiohttp/client.py", line 760, in _request
    resp = await handler(req)
           ^^^^^^^^^^^^^^^^^^
  File "/root/Reymond/lib/aiohttp/client.py", line 715, in _connect_and_send_request
    conn = await self._connector.connect(
           ^^^^^^^^^^^^^^^^^^^^^^^^^^^^^^
  File "/root/Reymond/lib/aiohttp/connector.py", line 561, in connect
    proto = await self._create_connection(req, traces, timeout)
            ^^^^^^^^^^^^^^^^^^^^^^^^^^^^^^^^^^^^^^^^^^^^^^^^^^^
  File "/root/Reymond/lib/aiohttp/connector.py", line 1074, in _create_connection
    _, proto = await self._create_direct_connection(req, traces, timeout)
               ^^^^^^^^^^^^^^^^^^^^^^^^^^^^^^^^^^^^^^^^^^^^^^^^^^^^^^^^^^
  File "/root/Reymond/lib/aiohttp/connector.py", line 1394, in _create_direct_connection
    transp, proto = await self._wrap_create_connection(
                    ^^^^^^^^^^^^^^^^^^^^^^^^^^^^^^^^^^^
  File "/root/Reymond/lib/aiohttp/connector.py", line 1141, in _wrap_create_connection
    return await self._loop.create_connection(*args, **kwargs, sock=sock)
           ^^^^^^^^^^^^^^^^^^^^^^^^^^^^^^^^^^^^^^^^^^^^^^^^^^^^^^^^^^^^^^
  File "/usr/lib/python3.12/asyncio/base_events.py", line 1149, in create_connection
    transport, protocol = await self._create_connection_transport(
                          ^^^^^^^^^^^^^^^^^^^^^^^^^^^^^^^^^^^^^^^^
  File "/usr/lib/python3.12/asyncio/base_events.py", line 1182, in _create_connection_transport
    await waiter
asyncio.exceptions.CancelledError

The above exception was the direct cause of the following exception:

Traceback (most recent call last):
  File "/root/Reymond/lib/discord/client.py", line 701, in connect
    self.ws = await asyncio.wait_for(coro, timeout=60.0)
              ^^^^^^^^^^^^^^^^^^^^^^^^^^^^^^^^^^^^^^^^^^
  File "/usr/lib/python3.12/asyncio/tasks.py", line 519, in wait_for
    async with timeouts.timeout(timeout):
  File "/usr/lib/python3.12/asyncio/timeouts.py", line 115, in __aexit__
    raise TimeoutError from exc_val
TimeoutError
[2025-07-24 22:22:42] [ERROR   ] discord.client: Attempting a reconnect in 5.09s
Traceback (most recent call last):
  File "/usr/lib/python3.12/asyncio/tasks.py", line 520, in wait_for
    return await fut
           ^^^^^^^^^
  File "/root/Reymond/lib/discord/gateway.py", line 375, in from_client
    socket = await client.http.ws_connect(str(url))
             ^^^^^^^^^^^^^^^^^^^^^^^^^^^^^^^^^^^^^^
  File "/root/Reymond/lib/discord/http.py", line 554, in ws_connect
    return await self.__session.ws_connect(url, **kwargs)
           ^^^^^^^^^^^^^^^^^^^^^^^^^^^^^^^^^^^^^^^^^^^^^^
  File "/root/Reymond/lib/aiohttp/client.py", line 1048, in _ws_connect
    resp = await self.request(
           ^^^^^^^^^^^^^^^^^^^
  File "/root/Reymond/lib/aiohttp/client.py", line 760, in _request
    resp = await handler(req)
           ^^^^^^^^^^^^^^^^^^
  File "/root/Reymond/lib/aiohttp/client.py", line 715, in _connect_and_send_request
    conn = await self._connector.connect(
           ^^^^^^^^^^^^^^^^^^^^^^^^^^^^^^
  File "/root/Reymond/lib/aiohttp/connector.py", line 561, in connect
    proto = await self._create_connection(req, traces, timeout)
            ^^^^^^^^^^^^^^^^^^^^^^^^^^^^^^^^^^^^^^^^^^^^^^^^^^^
  File "/root/Reymond/lib/aiohttp/connector.py", line 1074, in _create_connection
    _, proto = await self._create_direct_connection(req, traces, timeout)
               ^^^^^^^^^^^^^^^^^^^^^^^^^^^^^^^^^^^^^^^^^^^^^^^^^^^^^^^^^^
  File "/root/Reymond/lib/aiohttp/connector.py", line 1394, in _create_direct_connection
    transp, proto = await self._wrap_create_connection(
                    ^^^^^^^^^^^^^^^^^^^^^^^^^^^^^^^^^^^
  File "/root/Reymond/lib/aiohttp/connector.py", line 1141, in _wrap_create_connection
    return await self._loop.create_connection(*args, **kwargs, sock=sock)
           ^^^^^^^^^^^^^^^^^^^^^^^^^^^^^^^^^^^^^^^^^^^^^^^^^^^^^^^^^^^^^^
  File "/usr/lib/python3.12/asyncio/base_events.py", line 1149, in create_connection
    transport, protocol = await self._create_connection_transport(
                          ^^^^^^^^^^^^^^^^^^^^^^^^^^^^^^^^^^^^^^^^
  File "/usr/lib/python3.12/asyncio/base_events.py", line 1182, in _create_connection_transport
    await waiter
asyncio.exceptions.CancelledError

The above exception was the direct cause of the following exception:

Traceback (most recent call last):
  File "/root/Reymond/lib/discord/client.py", line 701, in connect
    self.ws = await asyncio.wait_for(coro, timeout=60.0)
              ^^^^^^^^^^^^^^^^^^^^^^^^^^^^^^^^^^^^^^^^^^
  File "/usr/lib/python3.12/asyncio/tasks.py", line 519, in wait_for
    async with timeouts.timeout(timeout):
  File "/usr/lib/python3.12/asyncio/timeouts.py", line 115, in __aexit__
    raise TimeoutError from exc_val
TimeoutError
[2025-07-24 22:23:47] [ERROR   ] discord.client: Attempting a reconnect in 8.03s
Traceback (most recent call last):
  File "/usr/lib/python3.12/asyncio/tasks.py", line 520, in wait_for
    return await fut
           ^^^^^^^^^
  File "/root/Reymond/lib/discord/gateway.py", line 375, in from_client
    socket = await client.http.ws_connect(str(url))
             ^^^^^^^^^^^^^^^^^^^^^^^^^^^^^^^^^^^^^^
  File "/root/Reymond/lib/discord/http.py", line 554, in ws_connect
    return await self.__session.ws_connect(url, **kwargs)
           ^^^^^^^^^^^^^^^^^^^^^^^^^^^^^^^^^^^^^^^^^^^^^^
  File "/root/Reymond/lib/aiohttp/client.py", line 1048, in _ws_connect
    resp = await self.request(
           ^^^^^^^^^^^^^^^^^^^
  File "/root/Reymond/lib/aiohttp/client.py", line 760, in _request
    resp = await handler(req)
           ^^^^^^^^^^^^^^^^^^
  File "/root/Reymond/lib/aiohttp/client.py", line 715, in _connect_and_send_request
    conn = await self._connector.connect(
           ^^^^^^^^^^^^^^^^^^^^^^^^^^^^^^
  File "/root/Reymond/lib/aiohttp/connector.py", line 561, in connect
    proto = await self._create_connection(req, traces, timeout)
            ^^^^^^^^^^^^^^^^^^^^^^^^^^^^^^^^^^^^^^^^^^^^^^^^^^^
  File "/root/Reymond/lib/aiohttp/connector.py", line 1074, in _create_connection
    _, proto = await self._create_direct_connection(req, traces, timeout)
               ^^^^^^^^^^^^^^^^^^^^^^^^^^^^^^^^^^^^^^^^^^^^^^^^^^^^^^^^^^
  File "/root/Reymond/lib/aiohttp/connector.py", line 1394, in _create_direct_connection
    transp, proto = await self._wrap_create_connection(
                    ^^^^^^^^^^^^^^^^^^^^^^^^^^^^^^^^^^^
  File "/root/Reymond/lib/aiohttp/connector.py", line 1141, in _wrap_create_connection
    return await self._loop.create_connection(*args, **kwargs, sock=sock)
           ^^^^^^^^^^^^^^^^^^^^^^^^^^^^^^^^^^^^^^^^^^^^^^^^^^^^^^^^^^^^^^
  File "/usr/lib/python3.12/asyncio/base_events.py", line 1149, in create_connection
    transport, protocol = await self._create_connection_transport(
                          ^^^^^^^^^^^^^^^^^^^^^^^^^^^^^^^^^^^^^^^^
  File "/usr/lib/python3.12/asyncio/base_events.py", line 1182, in _create_connection_transport
    await waiter
asyncio.exceptions.CancelledError

The above exception was the direct cause of the following exception:

Traceback (most recent call last):
  File "/root/Reymond/lib/discord/client.py", line 701, in connect
    self.ws = await asyncio.wait_for(coro, timeout=60.0)
              ^^^^^^^^^^^^^^^^^^^^^^^^^^^^^^^^^^^^^^^^^^
  File "/usr/lib/python3.12/asyncio/tasks.py", line 519, in wait_for
    async with timeouts.timeout(timeout):
  File "/usr/lib/python3.12/asyncio/timeouts.py", line 115, in __aexit__
    raise TimeoutError from exc_val
TimeoutError
[2025-07-24 22:24:55] [ERROR   ] discord.client: Attempting a reconnect in 29.16s
Traceback (most recent call last):
  File "/usr/lib/python3.12/asyncio/tasks.py", line 520, in wait_for
    return await fut
           ^^^^^^^^^
  File "/root/Reymond/lib/discord/gateway.py", line 375, in from_client
    socket = await client.http.ws_connect(str(url))
             ^^^^^^^^^^^^^^^^^^^^^^^^^^^^^^^^^^^^^^
  File "/root/Reymond/lib/discord/http.py", line 554, in ws_connect
    return await self.__session.ws_connect(url, **kwargs)
           ^^^^^^^^^^^^^^^^^^^^^^^^^^^^^^^^^^^^^^^^^^^^^^
  File "/root/Reymond/lib/aiohttp/client.py", line 1048, in _ws_connect
    resp = await self.request(
           ^^^^^^^^^^^^^^^^^^^
  File "/root/Reymond/lib/aiohttp/client.py", line 760, in _request
    resp = await handler(req)
           ^^^^^^^^^^^^^^^^^^
  File "/root/Reymond/lib/aiohttp/client.py", line 715, in _connect_and_send_request
    conn = await self._connector.connect(
           ^^^^^^^^^^^^^^^^^^^^^^^^^^^^^^
  File "/root/Reymond/lib/aiohttp/connector.py", line 561, in connect
    proto = await self._create_connection(req, traces, timeout)
            ^^^^^^^^^^^^^^^^^^^^^^^^^^^^^^^^^^^^^^^^^^^^^^^^^^^
  File "/root/Reymond/lib/aiohttp/connector.py", line 1074, in _create_connection
    _, proto = await self._create_direct_connection(req, traces, timeout)
               ^^^^^^^^^^^^^^^^^^^^^^^^^^^^^^^^^^^^^^^^^^^^^^^^^^^^^^^^^^
  File "/root/Reymond/lib/aiohttp/connector.py", line 1394, in _create_direct_connection
    transp, proto = await self._wrap_create_connection(
                    ^^^^^^^^^^^^^^^^^^^^^^^^^^^^^^^^^^^
  File "/root/Reymond/lib/aiohttp/connector.py", line 1141, in _wrap_create_connection
    return await self._loop.create_connection(*args, **kwargs, sock=sock)
           ^^^^^^^^^^^^^^^^^^^^^^^^^^^^^^^^^^^^^^^^^^^^^^^^^^^^^^^^^^^^^^
  File "/usr/lib/python3.12/asyncio/base_events.py", line 1149, in create_connection
    transport, protocol = await self._create_connection_transport(
                          ^^^^^^^^^^^^^^^^^^^^^^^^^^^^^^^^^^^^^^^^
  File "/usr/lib/python3.12/asyncio/base_events.py", line 1182, in _create_connection_transport
    await waiter
asyncio.exceptions.CancelledError

The above exception was the direct cause of the following exception:

Traceback (most recent call last):
  File "/root/Reymond/lib/discord/client.py", line 701, in connect
    self.ws = await asyncio.wait_for(coro, timeout=60.0)
              ^^^^^^^^^^^^^^^^^^^^^^^^^^^^^^^^^^^^^^^^^^
  File "/usr/lib/python3.12/asyncio/tasks.py", line 519, in wait_for
    async with timeouts.timeout(timeout):
  File "/usr/lib/python3.12/asyncio/timeouts.py", line 115, in __aexit__
    raise TimeoutError from exc_val
TimeoutError
[2025-07-24 22:26:24] [ERROR   ] discord.client: Attempting a reconnect in 37.47s
Traceback (most recent call last):
  File "/usr/lib/python3.12/asyncio/tasks.py", line 520, in wait_for
    return await fut
           ^^^^^^^^^
  File "/root/Reymond/lib/discord/gateway.py", line 375, in from_client
    socket = await client.http.ws_connect(str(url))
             ^^^^^^^^^^^^^^^^^^^^^^^^^^^^^^^^^^^^^^
  File "/root/Reymond/lib/discord/http.py", line 554, in ws_connect
    return await self.__session.ws_connect(url, **kwargs)
           ^^^^^^^^^^^^^^^^^^^^^^^^^^^^^^^^^^^^^^^^^^^^^^
  File "/root/Reymond/lib/aiohttp/client.py", line 1048, in _ws_connect
    resp = await self.request(
           ^^^^^^^^^^^^^^^^^^^
  File "/root/Reymond/lib/aiohttp/client.py", line 760, in _request
    resp = await handler(req)
           ^^^^^^^^^^^^^^^^^^
  File "/root/Reymond/lib/aiohttp/client.py", line 715, in _connect_and_send_request
    conn = await self._connector.connect(
           ^^^^^^^^^^^^^^^^^^^^^^^^^^^^^^
  File "/root/Reymond/lib/aiohttp/connector.py", line 561, in connect
    proto = await self._create_connection(req, traces, timeout)
            ^^^^^^^^^^^^^^^^^^^^^^^^^^^^^^^^^^^^^^^^^^^^^^^^^^^
  File "/root/Reymond/lib/aiohttp/connector.py", line 1074, in _create_connection
    _, proto = await self._create_direct_connection(req, traces, timeout)
               ^^^^^^^^^^^^^^^^^^^^^^^^^^^^^^^^^^^^^^^^^^^^^^^^^^^^^^^^^^
  File "/root/Reymond/lib/aiohttp/connector.py", line 1394, in _create_direct_connection
    transp, proto = await self._wrap_create_connection(
                    ^^^^^^^^^^^^^^^^^^^^^^^^^^^^^^^^^^^
  File "/root/Reymond/lib/aiohttp/connector.py", line 1141, in _wrap_create_connection
    return await self._loop.create_connection(*args, **kwargs, sock=sock)
           ^^^^^^^^^^^^^^^^^^^^^^^^^^^^^^^^^^^^^^^^^^^^^^^^^^^^^^^^^^^^^^
  File "/usr/lib/python3.12/asyncio/base_events.py", line 1149, in create_connection
    transport, protocol = await self._create_connection_transport(
                          ^^^^^^^^^^^^^^^^^^^^^^^^^^^^^^^^^^^^^^^^
  File "/usr/lib/python3.12/asyncio/base_events.py", line 1182, in _create_connection_transport
    await waiter
asyncio.exceptions.CancelledError

The above exception was the direct cause of the following exception:

Traceback (most recent call last):
  File "/root/Reymond/lib/discord/client.py", line 701, in connect
    self.ws = await asyncio.wait_for(coro, timeout=60.0)
              ^^^^^^^^^^^^^^^^^^^^^^^^^^^^^^^^^^^^^^^^^^
  File "/usr/lib/python3.12/asyncio/tasks.py", line 519, in wait_for
    async with timeouts.timeout(timeout):
  File "/usr/lib/python3.12/asyncio/timeouts.py", line 115, in __aexit__
    raise TimeoutError from exc_val
TimeoutError
[2025-07-24 22:28:02] [ERROR   ] discord.client: Attempting a reconnect in 112.32s
Traceback (most recent call last):
  File "/usr/lib/python3.12/asyncio/tasks.py", line 520, in wait_for
    return await fut
           ^^^^^^^^^
  File "/root/Reymond/lib/discord/gateway.py", line 375, in from_client
    socket = await client.http.ws_connect(str(url))
             ^^^^^^^^^^^^^^^^^^^^^^^^^^^^^^^^^^^^^^
  File "/root/Reymond/lib/discord/http.py", line 554, in ws_connect
    return await self.__session.ws_connect(url, **kwargs)
           ^^^^^^^^^^^^^^^^^^^^^^^^^^^^^^^^^^^^^^^^^^^^^^
  File "/root/Reymond/lib/aiohttp/client.py", line 1048, in _ws_connect
    resp = await self.request(
           ^^^^^^^^^^^^^^^^^^^
  File "/root/Reymond/lib/aiohttp/client.py", line 760, in _request
    resp = await handler(req)
           ^^^^^^^^^^^^^^^^^^
  File "/root/Reymond/lib/aiohttp/client.py", line 715, in _connect_and_send_request
    conn = await self._connector.connect(
           ^^^^^^^^^^^^^^^^^^^^^^^^^^^^^^
  File "/root/Reymond/lib/aiohttp/connector.py", line 561, in connect
    proto = await self._create_connection(req, traces, timeout)
            ^^^^^^^^^^^^^^^^^^^^^^^^^^^^^^^^^^^^^^^^^^^^^^^^^^^
  File "/root/Reymond/lib/aiohttp/connector.py", line 1074, in _create_connection
    _, proto = await self._create_direct_connection(req, traces, timeout)
               ^^^^^^^^^^^^^^^^^^^^^^^^^^^^^^^^^^^^^^^^^^^^^^^^^^^^^^^^^^
  File "/root/Reymond/lib/aiohttp/connector.py", line 1394, in _create_direct_connection
    transp, proto = await self._wrap_create_connection(
                    ^^^^^^^^^^^^^^^^^^^^^^^^^^^^^^^^^^^
  File "/root/Reymond/lib/aiohttp/connector.py", line 1141, in _wrap_create_connection
    return await self._loop.create_connection(*args, **kwargs, sock=sock)
           ^^^^^^^^^^^^^^^^^^^^^^^^^^^^^^^^^^^^^^^^^^^^^^^^^^^^^^^^^^^^^^
  File "/usr/lib/python3.12/asyncio/base_events.py", line 1149, in create_connection
    transport, protocol = await self._create_connection_transport(
                          ^^^^^^^^^^^^^^^^^^^^^^^^^^^^^^^^^^^^^^^^
  File "/usr/lib/python3.12/asyncio/base_events.py", line 1182, in _create_connection_transport
    await waiter
asyncio.exceptions.CancelledError

The above exception was the direct cause of the following exception:

Traceback (most recent call last):
  File "/root/Reymond/lib/discord/client.py", line 701, in connect
    self.ws = await asyncio.wait_for(coro, timeout=60.0)
              ^^^^^^^^^^^^^^^^^^^^^^^^^^^^^^^^^^^^^^^^^^
  File "/usr/lib/python3.12/asyncio/tasks.py", line 519, in wait_for
    async with timeouts.timeout(timeout):
  File "/usr/lib/python3.12/asyncio/timeouts.py", line 115, in __aexit__
    raise TimeoutError from exc_val
TimeoutError
[2025-07-24 22:30:10] [INFO    ] discord.gateway: Shard ID None session has been invalidated.
[2025-07-24 22:30:15] [INFO    ] discord.gateway: Shard ID None has connected to Gateway (Session ID: c506966ff7c6a307316a6d0aa469a6aa).
[2025-07-24 22:51:48] [ERROR   ] discord.client: Attempting a reconnect in 14.50s
Traceback (most recent call last):
  File "/usr/lib/python3.12/asyncio/tasks.py", line 520, in wait_for
    return await fut
           ^^^^^^^^^
  File "/root/Reymond/lib/discord/gateway.py", line 375, in from_client
    socket = await client.http.ws_connect(str(url))
             ^^^^^^^^^^^^^^^^^^^^^^^^^^^^^^^^^^^^^^
  File "/root/Reymond/lib/discord/http.py", line 554, in ws_connect
    return await self.__session.ws_connect(url, **kwargs)
           ^^^^^^^^^^^^^^^^^^^^^^^^^^^^^^^^^^^^^^^^^^^^^^
  File "/root/Reymond/lib/aiohttp/client.py", line 1048, in _ws_connect
    resp = await self.request(
           ^^^^^^^^^^^^^^^^^^^
  File "/root/Reymond/lib/aiohttp/client.py", line 760, in _request
    resp = await handler(req)
           ^^^^^^^^^^^^^^^^^^
  File "/root/Reymond/lib/aiohttp/client.py", line 715, in _connect_and_send_request
    conn = await self._connector.connect(
           ^^^^^^^^^^^^^^^^^^^^^^^^^^^^^^
  File "/root/Reymond/lib/aiohttp/connector.py", line 561, in connect
    proto = await self._create_connection(req, traces, timeout)
            ^^^^^^^^^^^^^^^^^^^^^^^^^^^^^^^^^^^^^^^^^^^^^^^^^^^
  File "/root/Reymond/lib/aiohttp/connector.py", line 1074, in _create_connection
    _, proto = await self._create_direct_connection(req, traces, timeout)
               ^^^^^^^^^^^^^^^^^^^^^^^^^^^^^^^^^^^^^^^^^^^^^^^^^^^^^^^^^^
  File "/root/Reymond/lib/aiohttp/connector.py", line 1394, in _create_direct_connection
    transp, proto = await self._wrap_create_connection(
                    ^^^^^^^^^^^^^^^^^^^^^^^^^^^^^^^^^^^
  File "/root/Reymond/lib/aiohttp/connector.py", line 1141, in _wrap_create_connection
    return await self._loop.create_connection(*args, **kwargs, sock=sock)
           ^^^^^^^^^^^^^^^^^^^^^^^^^^^^^^^^^^^^^^^^^^^^^^^^^^^^^^^^^^^^^^
  File "/usr/lib/python3.12/asyncio/base_events.py", line 1149, in create_connection
    transport, protocol = await self._create_connection_transport(
                          ^^^^^^^^^^^^^^^^^^^^^^^^^^^^^^^^^^^^^^^^
  File "/usr/lib/python3.12/asyncio/base_events.py", line 1182, in _create_connection_transport
    await waiter
asyncio.exceptions.CancelledError

The above exception was the direct cause of the following exception:

Traceback (most recent call last):
  File "/root/Reymond/lib/discord/client.py", line 701, in connect
    self.ws = await asyncio.wait_for(coro, timeout=60.0)
              ^^^^^^^^^^^^^^^^^^^^^^^^^^^^^^^^^^^^^^^^^^
  File "/usr/lib/python3.12/asyncio/tasks.py", line 519, in wait_for
    async with timeouts.timeout(timeout):
  File "/usr/lib/python3.12/asyncio/timeouts.py", line 115, in __aexit__
    raise TimeoutError from exc_val
TimeoutError
[2025-07-24 22:52:03] [INFO    ] discord.gateway: Shard ID None has successfully RESUMED session c506966ff7c6a307316a6d0aa469a6aa.
[2025-07-24 23:16:36] [INFO    ] discord.gateway: Shard ID None has successfully RESUMED session c506966ff7c6a307316a6d0aa469a6aa.
[2025-07-25 01:23:48] [INFO    ] discord.gateway: Shard ID None has successfully RESUMED session c506966ff7c6a307316a6d0aa469a6aa.
[2025-07-25 03:24:19] [INFO    ] discord.gateway: Shard ID None has successfully RESUMED session c506966ff7c6a307316a6d0aa469a6aa.
[2025-07-25 04:18:42] [INFO    ] discord.gateway: Shard ID None has successfully RESUMED session c506966ff7c6a307316a6d0aa469a6aa.
[2025-07-25 05:49:09] [INFO    ] discord.gateway: Shard ID None has successfully RESUMED session c506966ff7c6a307316a6d0aa469a6aa.
[2025-07-25 07:17:50] [INFO    ] discord.gateway: Shard ID None has successfully RESUMED session c506966ff7c6a307316a6d0aa469a6aa.
[2025-07-25 08:18:24] [INFO    ] discord.gateway: Shard ID None has successfully RESUMED session c506966ff7c6a307316a6d0aa469a6aa.
[2025-07-25 11:29:42] [INFO    ] discord.gateway: Shard ID None has successfully RESUMED session c506966ff7c6a307316a6d0aa469a6aa.
[2025-07-25 12:23:33] [INFO    ] discord.gateway: Shard ID None has successfully RESUMED session c506966ff7c6a307316a6d0aa469a6aa.
[2025-07-25 13:06:31] [ERROR   ] discord.app_commands.tree: Ignoring exception in command 'bank_list'
Traceback (most recent call last):
  File "/root/Reymond/lib/discord/app_commands/commands.py", line 858, in _do_call
    return await self._callback(interaction, **params)  # type: ignore
           ^^^^^^^^^^^^^^^^^^^^^^^^^^^^^^^^^^^^^^^^^^^
  File "/root/Reymond/main.py", line 1022, in bank_list
    await interaction.response.send_message(embed=embed, ephemeral=True)
  File "/root/Reymond/lib/discord/interactions.py", line 1004, in send_message
    response = await adapter.create_interaction_response(
               ^^^^^^^^^^^^^^^^^^^^^^^^^^^^^^^^^^^^^^^^^^
  File "/root/Reymond/lib/discord/webhook/async_.py", line 224, in request
    raise NotFound(response, data)
discord.errors.NotFound: 404 Not Found (error code: 10062): Unknown interaction

The above exception was the direct cause of the following exception:

Traceback (most recent call last):
  File "/root/Reymond/lib/discord/app_commands/tree.py", line 1310, in _call
    await command._invoke_with_namespace(interaction, namespace)
  File "/root/Reymond/lib/discord/app_commands/commands.py", line 883, in _invoke_with_namespace
    return await self._do_call(interaction, transformed_values)
           ^^^^^^^^^^^^^^^^^^^^^^^^^^^^^^^^^^^^^^^^^^^^^^^^^^^^
  File "/root/Reymond/lib/discord/app_commands/commands.py", line 876, in _do_call
    raise CommandInvokeError(self, e) from e
discord.app_commands.errors.CommandInvokeError: Command 'bank_list' raised an exception: NotFound: 404 Not Found (error code: 10062): Unknown interaction
[2025-07-25 13:06:40] [ERROR   ] discord.app_commands.tree: Ignoring exception in command 'bank_list'
Traceback (most recent call last):
  File "/root/Reymond/lib/discord/app_commands/commands.py", line 858, in _do_call
    return await self._callback(interaction, **params)  # type: ignore
           ^^^^^^^^^^^^^^^^^^^^^^^^^^^^^^^^^^^^^^^^^^^
  File "/root/Reymond/main.py", line 1022, in bank_list
    await interaction.response.send_message(embed=embed, ephemeral=True)
  File "/root/Reymond/lib/discord/interactions.py", line 1004, in send_message
    response = await adapter.create_interaction_response(
               ^^^^^^^^^^^^^^^^^^^^^^^^^^^^^^^^^^^^^^^^^^
  File "/root/Reymond/lib/discord/webhook/async_.py", line 224, in request
    raise NotFound(response, data)
discord.errors.NotFound: 404 Not Found (error code: 10062): Unknown interaction

The above exception was the direct cause of the following exception:

Traceback (most recent call last):
  File "/root/Reymond/lib/discord/app_commands/tree.py", line 1310, in _call
    await command._invoke_with_namespace(interaction, namespace)
  File "/root/Reymond/lib/discord/app_commands/commands.py", line 883, in _invoke_with_namespace
    return await self._do_call(interaction, transformed_values)
           ^^^^^^^^^^^^^^^^^^^^^^^^^^^^^^^^^^^^^^^^^^^^^^^^^^^^
  File "/root/Reymond/lib/discord/app_commands/commands.py", line 876, in _do_call
    raise CommandInvokeError(self, e) from e
discord.app_commands.errors.CommandInvokeError: Command 'bank_list' raised an exception: NotFound: 404 Not Found (error code: 10062): Unknown interaction
[2025-07-25 13:36:42] [INFO    ] discord.gateway: Shard ID None has successfully RESUMED session c506966ff7c6a307316a6d0aa469a6aa.
[2025-07-25 16:47:15] [INFO    ] discord.gateway: Shard ID None has successfully RESUMED session c506966ff7c6a307316a6d0aa469a6aa.
[2025-07-25 18:24:43] [INFO    ] discord.gateway: Shard ID None has successfully RESUMED session c506966ff7c6a307316a6d0aa469a6aa.
[2025-07-25 22:09:44] [INFO    ] discord.gateway: Shard ID None has successfully RESUMED session c506966ff7c6a307316a6d0aa469a6aa.
[2025-07-25 22:52:02] [INFO    ] discord.gateway: Shard ID None has successfully RESUMED session c506966ff7c6a307316a6d0aa469a6aa.
[2025-07-26 01:09:50] [INFO    ] discord.gateway: Shard ID None has successfully RESUMED session c506966ff7c6a307316a6d0aa469a6aa.
[2025-07-26 02:12:55] [INFO    ] discord.gateway: Shard ID None has successfully RESUMED session c506966ff7c6a307316a6d0aa469a6aa.
[2025-07-26 03:08:06] [INFO    ] discord.gateway: Shard ID None has successfully RESUMED session c506966ff7c6a307316a6d0aa469a6aa.
[2025-07-26 03:44:13] [INFO    ] discord.gateway: Shard ID None has successfully RESUMED session c506966ff7c6a307316a6d0aa469a6aa.
[2025-07-26 04:05:51] [INFO    ] discord.gateway: Shard ID None has successfully RESUMED session c506966ff7c6a307316a6d0aa469a6aa.
[2025-07-26 04:16:51] [INFO    ] discord.gateway: Shard ID None has successfully RESUMED session c506966ff7c6a307316a6d0aa469a6aa.
[2025-07-26 04:28:43] [INFO    ] discord.gateway: Shard ID None has successfully RESUMED session c506966ff7c6a307316a6d0aa469a6aa.
[2025-07-26 05:12:37] [INFO    ] discord.gateway: Shard ID None has successfully RESUMED session c506966ff7c6a307316a6d0aa469a6aa.
[2025-07-26 06:33:10] [INFO    ] discord.gateway: Shard ID None has successfully RESUMED session c506966ff7c6a307316a6d0aa469a6aa.
[2025-07-26 08:28:55] [INFO    ] discord.gateway: Shard ID None has successfully RESUMED session c506966ff7c6a307316a6d0aa469a6aa.
[2025-07-26 10:31:42] [INFO    ] discord.gateway: Shard ID None has successfully RESUMED session c506966ff7c6a307316a6d0aa469a6aa.
[2025-07-26 11:52:58] [INFO    ] discord.gateway: Shard ID None has successfully RESUMED session c506966ff7c6a307316a6d0aa469a6aa.
[2025-07-26 13:42:13] [ERROR   ] discord.app_commands.tree: Ignoring exception in command 'bank_list'
Traceback (most recent call last):
  File "/root/Reymond/lib/discord/app_commands/commands.py", line 858, in _do_call
    return await self._callback(interaction, **params)  # type: ignore
           ^^^^^^^^^^^^^^^^^^^^^^^^^^^^^^^^^^^^^^^^^^^
  File "/root/Reymond/main.py", line 1022, in bank_list
    await interaction.response.send_message(embed=embed, ephemeral=True)
  File "/root/Reymond/lib/discord/interactions.py", line 1004, in send_message
    response = await adapter.create_interaction_response(
               ^^^^^^^^^^^^^^^^^^^^^^^^^^^^^^^^^^^^^^^^^^
  File "/root/Reymond/lib/discord/webhook/async_.py", line 224, in request
    raise NotFound(response, data)
discord.errors.NotFound: 404 Not Found (error code: 10062): Unknown interaction

The above exception was the direct cause of the following exception:

Traceback (most recent call last):
  File "/root/Reymond/lib/discord/app_commands/tree.py", line 1310, in _call
    await command._invoke_with_namespace(interaction, namespace)
  File "/root/Reymond/lib/discord/app_commands/commands.py", line 883, in _invoke_with_namespace
    return await self._do_call(interaction, transformed_values)
           ^^^^^^^^^^^^^^^^^^^^^^^^^^^^^^^^^^^^^^^^^^^^^^^^^^^^
  File "/root/Reymond/lib/discord/app_commands/commands.py", line 876, in _do_call
    raise CommandInvokeError(self, e) from e
discord.app_commands.errors.CommandInvokeError: Command 'bank_list' raised an exception: NotFound: 404 Not Found (error code: 10062): Unknown interaction
[2025-07-26 14:34:01] [ERROR   ] discord.app_commands.tree: Ignoring exception in command 'bank_list'
Traceback (most recent call last):
  File "/root/Reymond/lib/discord/app_commands/commands.py", line 858, in _do_call
    return await self._callback(interaction, **params)  # type: ignore
           ^^^^^^^^^^^^^^^^^^^^^^^^^^^^^^^^^^^^^^^^^^^
  File "/root/Reymond/main.py", line 1022, in bank_list
    await interaction.response.send_message(embed=embed, ephemeral=True)
  File "/root/Reymond/lib/discord/interactions.py", line 1004, in send_message
    response = await adapter.create_interaction_response(
               ^^^^^^^^^^^^^^^^^^^^^^^^^^^^^^^^^^^^^^^^^^
  File "/root/Reymond/lib/discord/webhook/async_.py", line 224, in request
    raise NotFound(response, data)
discord.errors.NotFound: 404 Not Found (error code: 10062): Unknown interaction

The above exception was the direct cause of the following exception:

Traceback (most recent call last):
  File "/root/Reymond/lib/discord/app_commands/tree.py", line 1310, in _call
    await command._invoke_with_namespace(interaction, namespace)
  File "/root/Reymond/lib/discord/app_commands/commands.py", line 883, in _invoke_with_namespace
    return await self._do_call(interaction, transformed_values)
           ^^^^^^^^^^^^^^^^^^^^^^^^^^^^^^^^^^^^^^^^^^^^^^^^^^^^
  File "/root/Reymond/lib/discord/app_commands/commands.py", line 876, in _do_call
    raise CommandInvokeError(self, e) from e
discord.app_commands.errors.CommandInvokeError: Command 'bank_list' raised an exception: NotFound: 404 Not Found (error code: 10062): Unknown interaction
[2025-07-26 15:28:04] [INFO    ] discord.gateway: Shard ID None has successfully RESUMED session c506966ff7c6a307316a6d0aa469a6aa.
[2025-07-26 19:10:12] [INFO    ] discord.gateway: Shard ID None has successfully RESUMED session c506966ff7c6a307316a6d0aa469a6aa.
[2025-07-26 20:53:48] [INFO    ] discord.gateway: Shard ID None has successfully RESUMED session c506966ff7c6a307316a6d0aa469a6aa.
[2025-07-26 23:58:54] [INFO    ] discord.gateway: Shard ID None has successfully RESUMED session c506966ff7c6a307316a6d0aa469a6aa.
[2025-07-27 03:18:51] [INFO    ] discord.gateway: Shard ID None has successfully RESUMED session c506966ff7c6a307316a6d0aa469a6aa.
[2025-07-27 05:47:22] [INFO    ] discord.gateway: Shard ID None has successfully RESUMED session c506966ff7c6a307316a6d0aa469a6aa.
[2025-07-27 07:29:33] [INFO    ] discord.gateway: Shard ID None has successfully RESUMED session c506966ff7c6a307316a6d0aa469a6aa.
[2025-07-27 07:55:23] [INFO    ] discord.gateway: Shard ID None has successfully RESUMED session c506966ff7c6a307316a6d0aa469a6aa.
[2025-07-27 11:32:12] [INFO    ] discord.gateway: Shard ID None has successfully RESUMED session c506966ff7c6a307316a6d0aa469a6aa.
[2025-07-27 15:10:48] [INFO    ] discord.gateway: Shard ID None has successfully RESUMED session c506966ff7c6a307316a6d0aa469a6aa.
[2025-07-27 16:36:55] [INFO    ] discord.gateway: Shard ID None has successfully RESUMED session c506966ff7c6a307316a6d0aa469a6aa.
[2025-07-27 19:28:29] [INFO    ] discord.gateway: Shard ID None has successfully RESUMED session c506966ff7c6a307316a6d0aa469a6aa.
[2025-07-27 22:07:52] [INFO    ] discord.gateway: Shard ID None has successfully RESUMED session c506966ff7c6a307316a6d0aa469a6aa.
[2025-07-28 00:51:03] [INFO    ] discord.gateway: Shard ID None has successfully RESUMED session c506966ff7c6a307316a6d0aa469a6aa.
[2025-07-28 01:09:24] [INFO    ] discord.gateway: Shard ID None has successfully RESUMED session c506966ff7c6a307316a6d0aa469a6aa.
[2025-07-28 02:47:04] [INFO    ] discord.gateway: Shard ID None has successfully RESUMED session c506966ff7c6a307316a6d0aa469a6aa.
[2025-07-28 03:09:59] [ERROR   ] discord.client: Attempting a reconnect in 0.56s
Traceback (most recent call last):
  File "/usr/lib/python3.12/asyncio/tasks.py", line 520, in wait_for
    return await fut
           ^^^^^^^^^
  File "/root/Reymond/lib/discord/gateway.py", line 375, in from_client
    socket = await client.http.ws_connect(str(url))
             ^^^^^^^^^^^^^^^^^^^^^^^^^^^^^^^^^^^^^^
  File "/root/Reymond/lib/discord/http.py", line 554, in ws_connect
    return await self.__session.ws_connect(url, **kwargs)
           ^^^^^^^^^^^^^^^^^^^^^^^^^^^^^^^^^^^^^^^^^^^^^^
  File "/root/Reymond/lib/aiohttp/client.py", line 1048, in _ws_connect
    resp = await self.request(
           ^^^^^^^^^^^^^^^^^^^
  File "/root/Reymond/lib/aiohttp/client.py", line 760, in _request
    resp = await handler(req)
           ^^^^^^^^^^^^^^^^^^
  File "/root/Reymond/lib/aiohttp/client.py", line 715, in _connect_and_send_request
    conn = await self._connector.connect(
           ^^^^^^^^^^^^^^^^^^^^^^^^^^^^^^
  File "/root/Reymond/lib/aiohttp/connector.py", line 561, in connect
    proto = await self._create_connection(req, traces, timeout)
            ^^^^^^^^^^^^^^^^^^^^^^^^^^^^^^^^^^^^^^^^^^^^^^^^^^^
  File "/root/Reymond/lib/aiohttp/connector.py", line 1074, in _create_connection
    _, proto = await self._create_direct_connection(req, traces, timeout)
               ^^^^^^^^^^^^^^^^^^^^^^^^^^^^^^^^^^^^^^^^^^^^^^^^^^^^^^^^^^
  File "/root/Reymond/lib/aiohttp/connector.py", line 1394, in _create_direct_connection
    transp, proto = await self._wrap_create_connection(
                    ^^^^^^^^^^^^^^^^^^^^^^^^^^^^^^^^^^^
  File "/root/Reymond/lib/aiohttp/connector.py", line 1141, in _wrap_create_connection
    return await self._loop.create_connection(*args, **kwargs, sock=sock)
           ^^^^^^^^^^^^^^^^^^^^^^^^^^^^^^^^^^^^^^^^^^^^^^^^^^^^^^^^^^^^^^
  File "/usr/lib/python3.12/asyncio/base_events.py", line 1149, in create_connection
    transport, protocol = await self._create_connection_transport(
                          ^^^^^^^^^^^^^^^^^^^^^^^^^^^^^^^^^^^^^^^^
  File "/usr/lib/python3.12/asyncio/base_events.py", line 1182, in _create_connection_transport
    await waiter
asyncio.exceptions.CancelledError

The above exception was the direct cause of the following exception:

Traceback (most recent call last):
  File "/root/Reymond/lib/discord/client.py", line 701, in connect
    self.ws = await asyncio.wait_for(coro, timeout=60.0)
              ^^^^^^^^^^^^^^^^^^^^^^^^^^^^^^^^^^^^^^^^^^
  File "/usr/lib/python3.12/asyncio/tasks.py", line 519, in wait_for
    async with timeouts.timeout(timeout):
  File "/usr/lib/python3.12/asyncio/timeouts.py", line 115, in __aexit__
    raise TimeoutError from exc_val
TimeoutError
[2025-07-28 03:09:59] [INFO    ] discord.gateway: Shard ID None has successfully RESUMED session c506966ff7c6a307316a6d0aa469a6aa.
[2025-07-28 05:38:37] [INFO    ] discord.gateway: Shard ID None has successfully RESUMED session c506966ff7c6a307316a6d0aa469a6aa.
[2025-07-28 06:21:03] [INFO    ] discord.gateway: Shard ID None has successfully RESUMED session c506966ff7c6a307316a6d0aa469a6aa.
[2025-07-28 07:05:36] [INFO    ] discord.gateway: Shard ID None has successfully RESUMED session c506966ff7c6a307316a6d0aa469a6aa.
[2025-07-28 09:29:28] [INFO    ] discord.gateway: Shard ID None has successfully RESUMED session c506966ff7c6a307316a6d0aa469a6aa.
[2025-07-28 09:58:51] [INFO    ] discord.gateway: Shard ID None has successfully RESUMED session c506966ff7c6a307316a6d0aa469a6aa.
[2025-07-28 10:37:52] [INFO    ] discord.gateway: Shard ID None has successfully RESUMED session c506966ff7c6a307316a6d0aa469a6aa.
[2025-07-28 12:45:20] [INFO    ] discord.gateway: Shard ID None has successfully RESUMED session c506966ff7c6a307316a6d0aa469a6aa.
[2025-07-28 14:24:18] [INFO    ] discord.gateway: Shard ID None has successfully RESUMED session c506966ff7c6a307316a6d0aa469a6aa.
[2025-07-28 15:26:11] [INFO    ] discord.gateway: Shard ID None has successfully RESUMED session c506966ff7c6a307316a6d0aa469a6aa.
[2025-07-28 16:26:53] [INFO    ] discord.gateway: Shard ID None has successfully RESUMED session c506966ff7c6a307316a6d0aa469a6aa.
[2025-07-28 17:19:55] [INFO    ] discord.gateway: Shard ID None has successfully RESUMED session c506966ff7c6a307316a6d0aa469a6aa.
[2025-07-28 20:39:22] [INFO    ] discord.gateway: Shard ID None has successfully RESUMED session c506966ff7c6a307316a6d0aa469a6aa.
[2025-07-28 21:30:05] [ERROR   ] discord.client: Attempting a reconnect in 0.28s
Traceback (most recent call last):
  File "/usr/lib/python3.12/asyncio/tasks.py", line 520, in wait_for
    return await fut
           ^^^^^^^^^
  File "/root/Reymond/lib/discord/gateway.py", line 375, in from_client
    socket = await client.http.ws_connect(str(url))
             ^^^^^^^^^^^^^^^^^^^^^^^^^^^^^^^^^^^^^^
  File "/root/Reymond/lib/discord/http.py", line 554, in ws_connect
    return await self.__session.ws_connect(url, **kwargs)
           ^^^^^^^^^^^^^^^^^^^^^^^^^^^^^^^^^^^^^^^^^^^^^^
  File "/root/Reymond/lib/aiohttp/client.py", line 1048, in _ws_connect
    resp = await self.request(
           ^^^^^^^^^^^^^^^^^^^
  File "/root/Reymond/lib/aiohttp/client.py", line 760, in _request
    resp = await handler(req)
           ^^^^^^^^^^^^^^^^^^
  File "/root/Reymond/lib/aiohttp/client.py", line 715, in _connect_and_send_request
    conn = await self._connector.connect(
           ^^^^^^^^^^^^^^^^^^^^^^^^^^^^^^
  File "/root/Reymond/lib/aiohttp/connector.py", line 561, in connect
    proto = await self._create_connection(req, traces, timeout)
            ^^^^^^^^^^^^^^^^^^^^^^^^^^^^^^^^^^^^^^^^^^^^^^^^^^^
  File "/root/Reymond/lib/aiohttp/connector.py", line 1074, in _create_connection
    _, proto = await self._create_direct_connection(req, traces, timeout)
               ^^^^^^^^^^^^^^^^^^^^^^^^^^^^^^^^^^^^^^^^^^^^^^^^^^^^^^^^^^
  File "/root/Reymond/lib/aiohttp/connector.py", line 1394, in _create_direct_connection
    transp, proto = await self._wrap_create_connection(
                    ^^^^^^^^^^^^^^^^^^^^^^^^^^^^^^^^^^^
  File "/root/Reymond/lib/aiohttp/connector.py", line 1141, in _wrap_create_connection
    return await self._loop.create_connection(*args, **kwargs, sock=sock)
           ^^^^^^^^^^^^^^^^^^^^^^^^^^^^^^^^^^^^^^^^^^^^^^^^^^^^^^^^^^^^^^
  File "/usr/lib/python3.12/asyncio/base_events.py", line 1149, in create_connection
    transport, protocol = await self._create_connection_transport(
                          ^^^^^^^^^^^^^^^^^^^^^^^^^^^^^^^^^^^^^^^^
  File "/usr/lib/python3.12/asyncio/base_events.py", line 1182, in _create_connection_transport
    await waiter
asyncio.exceptions.CancelledError

The above exception was the direct cause of the following exception:

Traceback (most recent call last):
  File "/root/Reymond/lib/discord/client.py", line 701, in connect
    self.ws = await asyncio.wait_for(coro, timeout=60.0)
              ^^^^^^^^^^^^^^^^^^^^^^^^^^^^^^^^^^^^^^^^^^
  File "/usr/lib/python3.12/asyncio/tasks.py", line 519, in wait_for
    async with timeouts.timeout(timeout):
  File "/usr/lib/python3.12/asyncio/timeouts.py", line 115, in __aexit__
    raise TimeoutError from exc_val
TimeoutError
[2025-07-28 21:30:06] [INFO    ] discord.gateway: Shard ID None has successfully RESUMED session c506966ff7c6a307316a6d0aa469a6aa.
[2025-07-28 22:11:20] [INFO    ] discord.gateway: Shard ID None has successfully RESUMED session c506966ff7c6a307316a6d0aa469a6aa.
[2025-07-28 23:36:30] [INFO    ] discord.gateway: Shard ID None has successfully RESUMED session c506966ff7c6a307316a6d0aa469a6aa.
[2025-07-29 03:32:14] [INFO    ] discord.gateway: Shard ID None has successfully RESUMED session c506966ff7c6a307316a6d0aa469a6aa.
[2025-07-29 06:54:23] [INFO    ] discord.gateway: Shard ID None has successfully RESUMED session c506966ff7c6a307316a6d0aa469a6aa.
[2025-07-29 10:38:28] [INFO    ] discord.gateway: Shard ID None has successfully RESUMED session c506966ff7c6a307316a6d0aa469a6aa.
[2025-07-29 10:55:08] [INFO    ] discord.gateway: Shard ID None has successfully RESUMED session c506966ff7c6a307316a6d0aa469a6aa.
[2025-07-29 11:01:00] [INFO    ] discord.gateway: Shard ID None has successfully RESUMED session c506966ff7c6a307316a6d0aa469a6aa.
[2025-07-29 11:39:26] [INFO    ] discord.gateway: Shard ID None has successfully RESUMED session c506966ff7c6a307316a6d0aa469a6aa.
[2025-07-29 14:15:36] [INFO    ] discord.gateway: Shard ID None has successfully RESUMED session c506966ff7c6a307316a6d0aa469a6aa.
[2025-07-29 15:07:52] [INFO    ] discord.gateway: Shard ID None has successfully RESUMED session c506966ff7c6a307316a6d0aa469a6aa.
[2025-07-29 17:03:44] [INFO    ] discord.gateway: Shard ID None has successfully RESUMED session c506966ff7c6a307316a6d0aa469a6aa.
[2025-07-29 20:35:31] [INFO    ] discord.gateway: Shard ID None has successfully RESUMED session c506966ff7c6a307316a6d0aa469a6aa.
[2025-07-29 21:26:58] [INFO    ] discord.gateway: Shard ID None has successfully RESUMED session c506966ff7c6a307316a6d0aa469a6aa.
[2025-07-29 22:00:01] [INFO    ] discord.gateway: Shard ID None has successfully RESUMED session c506966ff7c6a307316a6d0aa469a6aa.
[2025-07-30 00:28:51] [INFO    ] discord.gateway: Shard ID None has successfully RESUMED session c506966ff7c6a307316a6d0aa469a6aa.
[2025-07-30 03:25:17] [INFO    ] discord.gateway: Shard ID None has successfully RESUMED session c506966ff7c6a307316a6d0aa469a6aa.
[2025-07-30 03:28:38] [INFO    ] discord.gateway: Shard ID None has successfully RESUMED session c506966ff7c6a307316a6d0aa469a6aa.
[2025-07-30 03:49:56] [INFO    ] discord.gateway: Shard ID None has successfully RESUMED session c506966ff7c6a307316a6d0aa469a6aa.
[2025-07-30 04:39:21] [INFO    ] discord.gateway: Shard ID None has successfully RESUMED session c506966ff7c6a307316a6d0aa469a6aa.
[2025-07-30 07:54:05] [INFO    ] discord.gateway: Shard ID None has successfully RESUMED session c506966ff7c6a307316a6d0aa469a6aa.
[2025-07-30 09:35:58] [INFO    ] discord.gateway: Shard ID None has successfully RESUMED session c506966ff7c6a307316a6d0aa469a6aa.
[2025-07-30 11:56:29] [INFO    ] discord.gateway: Shard ID None has successfully RESUMED session c506966ff7c6a307316a6d0aa469a6aa.
[2025-07-30 13:06:48] [INFO    ] discord.gateway: Shard ID None has successfully RESUMED session c506966ff7c6a307316a6d0aa469a6aa.
[2025-07-30 14:33:07] [INFO    ] discord.gateway: Shard ID None has successfully RESUMED session c506966ff7c6a307316a6d0aa469a6aa.
[2025-07-30 15:53:25] [INFO    ] discord.gateway: Shard ID None has successfully RESUMED session c506966ff7c6a307316a6d0aa469a6aa.
[2025-07-30 19:02:10] [INFO    ] discord.gateway: Shard ID None has successfully RESUMED session c506966ff7c6a307316a6d0aa469a6aa.
[2025-07-30 20:35:46] [INFO    ] discord.gateway: Shard ID None has successfully RESUMED session c506966ff7c6a307316a6d0aa469a6aa.
[2025-07-30 20:55:59] [INFO    ] discord.gateway: Shard ID None has successfully RESUMED session c506966ff7c6a307316a6d0aa469a6aa.
[2025-07-30 21:29:22] [INFO    ] discord.gateway: Shard ID None has successfully RESUMED session c506966ff7c6a307316a6d0aa469a6aa.
[2025-07-30 22:02:28] [INFO    ] discord.gateway: Shard ID None has successfully RESUMED session c506966ff7c6a307316a6d0aa469a6aa.
[2025-07-31 01:26:46] [INFO    ] discord.gateway: Shard ID None has successfully RESUMED session c506966ff7c6a307316a6d0aa469a6aa.
[2025-07-31 03:02:15] [ERROR   ] discord.client: Attempting a reconnect in 0.58s
Traceback (most recent call last):
  File "/usr/lib/python3.12/asyncio/tasks.py", line 520, in wait_for
    return await fut
           ^^^^^^^^^
  File "/root/Reymond/lib/discord/gateway.py", line 375, in from_client
    socket = await client.http.ws_connect(str(url))
             ^^^^^^^^^^^^^^^^^^^^^^^^^^^^^^^^^^^^^^
  File "/root/Reymond/lib/discord/http.py", line 554, in ws_connect
    return await self.__session.ws_connect(url, **kwargs)
           ^^^^^^^^^^^^^^^^^^^^^^^^^^^^^^^^^^^^^^^^^^^^^^
  File "/root/Reymond/lib/aiohttp/client.py", line 1048, in _ws_connect
    resp = await self.request(
           ^^^^^^^^^^^^^^^^^^^
  File "/root/Reymond/lib/aiohttp/client.py", line 760, in _request
    resp = await handler(req)
           ^^^^^^^^^^^^^^^^^^
  File "/root/Reymond/lib/aiohttp/client.py", line 715, in _connect_and_send_request
    conn = await self._connector.connect(
           ^^^^^^^^^^^^^^^^^^^^^^^^^^^^^^
  File "/root/Reymond/lib/aiohttp/connector.py", line 561, in connect
    proto = await self._create_connection(req, traces, timeout)
            ^^^^^^^^^^^^^^^^^^^^^^^^^^^^^^^^^^^^^^^^^^^^^^^^^^^
  File "/root/Reymond/lib/aiohttp/connector.py", line 1074, in _create_connection
    _, proto = await self._create_direct_connection(req, traces, timeout)
               ^^^^^^^^^^^^^^^^^^^^^^^^^^^^^^^^^^^^^^^^^^^^^^^^^^^^^^^^^^
  File "/root/Reymond/lib/aiohttp/connector.py", line 1394, in _create_direct_connection
    transp, proto = await self._wrap_create_connection(
                    ^^^^^^^^^^^^^^^^^^^^^^^^^^^^^^^^^^^
  File "/root/Reymond/lib/aiohttp/connector.py", line 1141, in _wrap_create_connection
    return await self._loop.create_connection(*args, **kwargs, sock=sock)
           ^^^^^^^^^^^^^^^^^^^^^^^^^^^^^^^^^^^^^^^^^^^^^^^^^^^^^^^^^^^^^^
  File "/usr/lib/python3.12/asyncio/base_events.py", line 1149, in create_connection
    transport, protocol = await self._create_connection_transport(
                          ^^^^^^^^^^^^^^^^^^^^^^^^^^^^^^^^^^^^^^^^
  File "/usr/lib/python3.12/asyncio/base_events.py", line 1182, in _create_connection_transport
    await waiter
asyncio.exceptions.CancelledError

The above exception was the direct cause of the following exception:

Traceback (most recent call last):
  File "/root/Reymond/lib/discord/client.py", line 701, in connect
    self.ws = await asyncio.wait_for(coro, timeout=60.0)
              ^^^^^^^^^^^^^^^^^^^^^^^^^^^^^^^^^^^^^^^^^^
  File "/usr/lib/python3.12/asyncio/tasks.py", line 519, in wait_for
    async with timeouts.timeout(timeout):
  File "/usr/lib/python3.12/asyncio/timeouts.py", line 115, in __aexit__
    raise TimeoutError from exc_val
TimeoutError
[2025-07-31 03:02:16] [INFO    ] discord.gateway: Shard ID None has successfully RESUMED session c506966ff7c6a307316a6d0aa469a6aa.
[2025-07-31 04:22:23] [INFO    ] discord.gateway: Shard ID None has successfully RESUMED session c506966ff7c6a307316a6d0aa469a6aa.
[2025-07-31 04:37:02] [INFO    ] discord.gateway: Shard ID None has successfully RESUMED session c506966ff7c6a307316a6d0aa469a6aa.
[2025-07-31 04:58:10] [ERROR   ] discord.client: Attempting a reconnect in 1.89s
Traceback (most recent call last):
  File "/usr/lib/python3.12/asyncio/tasks.py", line 520, in wait_for
    return await fut
           ^^^^^^^^^
  File "/root/Reymond/lib/discord/gateway.py", line 375, in from_client
    socket = await client.http.ws_connect(str(url))
             ^^^^^^^^^^^^^^^^^^^^^^^^^^^^^^^^^^^^^^
  File "/root/Reymond/lib/discord/http.py", line 554, in ws_connect
    return await self.__session.ws_connect(url, **kwargs)
           ^^^^^^^^^^^^^^^^^^^^^^^^^^^^^^^^^^^^^^^^^^^^^^
  File "/root/Reymond/lib/aiohttp/client.py", line 1048, in _ws_connect
    resp = await self.request(
           ^^^^^^^^^^^^^^^^^^^
  File "/root/Reymond/lib/aiohttp/client.py", line 760, in _request
    resp = await handler(req)
           ^^^^^^^^^^^^^^^^^^
  File "/root/Reymond/lib/aiohttp/client.py", line 715, in _connect_and_send_request
    conn = await self._connector.connect(
           ^^^^^^^^^^^^^^^^^^^^^^^^^^^^^^
  File "/root/Reymond/lib/aiohttp/connector.py", line 561, in connect
    proto = await self._create_connection(req, traces, timeout)
            ^^^^^^^^^^^^^^^^^^^^^^^^^^^^^^^^^^^^^^^^^^^^^^^^^^^
  File "/root/Reymond/lib/aiohttp/connector.py", line 1074, in _create_connection
    _, proto = await self._create_direct_connection(req, traces, timeout)
               ^^^^^^^^^^^^^^^^^^^^^^^^^^^^^^^^^^^^^^^^^^^^^^^^^^^^^^^^^^
  File "/root/Reymond/lib/aiohttp/connector.py", line 1394, in _create_direct_connection
    transp, proto = await self._wrap_create_connection(
                    ^^^^^^^^^^^^^^^^^^^^^^^^^^^^^^^^^^^
  File "/root/Reymond/lib/aiohttp/connector.py", line 1141, in _wrap_create_connection
    return await self._loop.create_connection(*args, **kwargs, sock=sock)
           ^^^^^^^^^^^^^^^^^^^^^^^^^^^^^^^^^^^^^^^^^^^^^^^^^^^^^^^^^^^^^^
  File "/usr/lib/python3.12/asyncio/base_events.py", line 1149, in create_connection
    transport, protocol = await self._create_connection_transport(
                          ^^^^^^^^^^^^^^^^^^^^^^^^^^^^^^^^^^^^^^^^
  File "/usr/lib/python3.12/asyncio/base_events.py", line 1182, in _create_connection_transport
    await waiter
asyncio.exceptions.CancelledError

The above exception was the direct cause of the following exception:

Traceback (most recent call last):
  File "/root/Reymond/lib/discord/client.py", line 701, in connect
    self.ws = await asyncio.wait_for(coro, timeout=60.0)
              ^^^^^^^^^^^^^^^^^^^^^^^^^^^^^^^^^^^^^^^^^^
  File "/usr/lib/python3.12/asyncio/tasks.py", line 519, in wait_for
    async with timeouts.timeout(timeout):
  File "/usr/lib/python3.12/asyncio/timeouts.py", line 115, in __aexit__
    raise TimeoutError from exc_val
TimeoutError
[2025-07-31 04:58:12] [INFO    ] discord.gateway: Shard ID None has successfully RESUMED session c506966ff7c6a307316a6d0aa469a6aa.
[2025-07-31 06:03:37] [INFO    ] discord.gateway: Shard ID None has successfully RESUMED session c506966ff7c6a307316a6d0aa469a6aa.
[2025-07-31 06:15:49] [INFO    ] discord.gateway: Shard ID None has successfully RESUMED session c506966ff7c6a307316a6d0aa469a6aa.
[2025-07-31 06:52:39] [INFO    ] discord.gateway: Shard ID None has successfully RESUMED session c506966ff7c6a307316a6d0aa469a6aa.
[2025-07-31 08:06:25] [INFO    ] discord.gateway: Shard ID None has successfully RESUMED session c506966ff7c6a307316a6d0aa469a6aa.
[2025-07-31 08:27:45] [INFO    ] discord.gateway: Shard ID None has successfully RESUMED session c506966ff7c6a307316a6d0aa469a6aa.
[2025-07-31 09:27:08] [ERROR   ] discord.app_commands.tree: Ignoring exception in command 'bank_list'
Traceback (most recent call last):
  File "/root/Reymond/lib/discord/app_commands/commands.py", line 858, in _do_call
    return await self._callback(interaction, **params)  # type: ignore
           ^^^^^^^^^^^^^^^^^^^^^^^^^^^^^^^^^^^^^^^^^^^
  File "/root/Reymond/main.py", line 1022, in bank_list
    await interaction.response.send_message(embed=embed, ephemeral=True)
  File "/root/Reymond/lib/discord/interactions.py", line 1004, in send_message
    response = await adapter.create_interaction_response(
               ^^^^^^^^^^^^^^^^^^^^^^^^^^^^^^^^^^^^^^^^^^
  File "/root/Reymond/lib/discord/webhook/async_.py", line 224, in request
    raise NotFound(response, data)
discord.errors.NotFound: 404 Not Found (error code: 10062): Unknown interaction

The above exception was the direct cause of the following exception:

Traceback (most recent call last):
  File "/root/Reymond/lib/discord/app_commands/tree.py", line 1310, in _call
    await command._invoke_with_namespace(interaction, namespace)
  File "/root/Reymond/lib/discord/app_commands/commands.py", line 883, in _invoke_with_namespace
    return await self._do_call(interaction, transformed_values)
           ^^^^^^^^^^^^^^^^^^^^^^^^^^^^^^^^^^^^^^^^^^^^^^^^^^^^
  File "/root/Reymond/lib/discord/app_commands/commands.py", line 876, in _do_call
    raise CommandInvokeError(self, e) from e
discord.app_commands.errors.CommandInvokeError: Command 'bank_list' raised an exception: NotFound: 404 Not Found (error code: 10062): Unknown interaction
[2025-07-31 09:28:03] [ERROR   ] discord.app_commands.tree: Ignoring exception in command 'bank_createcard'
Traceback (most recent call last):
  File "/root/Reymond/lib/discord/app_commands/commands.py", line 858, in _do_call
    return await self._callback(interaction, **params)  # type: ignore
           ^^^^^^^^^^^^^^^^^^^^^^^^^^^^^^^^^^^^^^^^^^^
  File "/root/Reymond/main.py", line 711, in bank_createcard
    await interaction.response.send_message(embed=embed, ephemeral=True)
  File "/root/Reymond/lib/discord/interactions.py", line 1004, in send_message
    response = await adapter.create_interaction_response(
               ^^^^^^^^^^^^^^^^^^^^^^^^^^^^^^^^^^^^^^^^^^
  File "/root/Reymond/lib/discord/webhook/async_.py", line 224, in request
    raise NotFound(response, data)
discord.errors.NotFound: 404 Not Found (error code: 10062): Unknown interaction

The above exception was the direct cause of the following exception:

Traceback (most recent call last):
  File "/root/Reymond/lib/discord/app_commands/tree.py", line 1310, in _call
    await command._invoke_with_namespace(interaction, namespace)
  File "/root/Reymond/lib/discord/app_commands/commands.py", line 883, in _invoke_with_namespace
    return await self._do_call(interaction, transformed_values)
           ^^^^^^^^^^^^^^^^^^^^^^^^^^^^^^^^^^^^^^^^^^^^^^^^^^^^
  File "/root/Reymond/lib/discord/app_commands/commands.py", line 876, in _do_call
    raise CommandInvokeError(self, e) from e
discord.app_commands.errors.CommandInvokeError: Command 'bank_createcard' raised an exception: NotFound: 404 Not Found (error code: 10062): Unknown interaction
[2025-07-31 10:36:30] [INFO    ] discord.gateway: Shard ID None has successfully RESUMED session c506966ff7c6a307316a6d0aa469a6aa.
[2025-07-31 12:02:02] [INFO    ] discord.gateway: Shard ID None has successfully RESUMED session c506966ff7c6a307316a6d0aa469a6aa.
[2025-07-31 14:22:56] [INFO    ] discord.gateway: Shard ID None has successfully RESUMED session c506966ff7c6a307316a6d0aa469a6aa.
[2025-07-31 14:58:15] [INFO    ] discord.gateway: Shard ID None has successfully RESUMED session c506966ff7c6a307316a6d0aa469a6aa.
[2025-07-31 17:36:32] [INFO    ] discord.gateway: Shard ID None has successfully RESUMED session c506966ff7c6a307316a6d0aa469a6aa.
[2025-07-31 17:48:19] [INFO    ] discord.gateway: Shard ID None has successfully RESUMED session c506966ff7c6a307316a6d0aa469a6aa.
[2025-07-31 18:09:36] [INFO    ] discord.gateway: Shard ID None has successfully RESUMED session c506966ff7c6a307316a6d0aa469a6aa.
[2025-07-31 19:05:45] [INFO    ] discord.gateway: Shard ID None has successfully RESUMED session c506966ff7c6a307316a6d0aa469a6aa.
[2025-07-31 20:08:44] [INFO    ] discord.gateway: Shard ID None has successfully RESUMED session c506966ff7c6a307316a6d0aa469a6aa.
[2025-07-31 23:02:35] [INFO    ] discord.gateway: Shard ID None has successfully RESUMED session c506966ff7c6a307316a6d0aa469a6aa.
[2025-07-31 23:11:00] [INFO    ] discord.gateway: Shard ID None has successfully RESUMED session c506966ff7c6a307316a6d0aa469a6aa.
[2025-08-01 00:31:39] [INFO    ] discord.gateway: Shard ID None has successfully RESUMED session c506966ff7c6a307316a6d0aa469a6aa.
[2025-08-01 03:16:39] [INFO    ] discord.gateway: Shard ID None has successfully RESUMED session c506966ff7c6a307316a6d0aa469a6aa.
[2025-08-01 06:45:26] [INFO    ] discord.gateway: Shard ID None has successfully RESUMED session c506966ff7c6a307316a6d0aa469a6aa.
[2025-08-01 08:40:00] [INFO    ] discord.gateway: Shard ID None has successfully RESUMED session c506966ff7c6a307316a6d0aa469a6aa.
[2025-08-01 11:23:54] [INFO    ] discord.gateway: Shard ID None has successfully RESUMED session c506966ff7c6a307316a6d0aa469a6aa.
[2025-08-01 11:55:35] [INFO    ] discord.gateway: Shard ID None has successfully RESUMED session c506966ff7c6a307316a6d0aa469a6aa.
[2025-08-01 13:13:34] [INFO    ] discord.gateway: Shard ID None has successfully RESUMED session c506966ff7c6a307316a6d0aa469a6aa.
[2025-08-01 14:59:33] [INFO    ] discord.gateway: Shard ID None has successfully RESUMED session c506966ff7c6a307316a6d0aa469a6aa.
[2025-08-01 15:44:23] [INFO    ] discord.gateway: Shard ID None has successfully RESUMED session c506966ff7c6a307316a6d0aa469a6aa.
[2025-08-01 17:33:07] [INFO    ] discord.gateway: Shard ID None has successfully RESUMED session c506966ff7c6a307316a6d0aa469a6aa.
[2025-08-01 20:47:22] [INFO    ] discord.gateway: Shard ID None has successfully RESUMED session c506966ff7c6a307316a6d0aa469a6aa.
[2025-08-01 22:48:00] [INFO    ] discord.gateway: Shard ID None has successfully RESUMED session c506966ff7c6a307316a6d0aa469a6aa.
[2025-08-02 02:22:24] [INFO    ] discord.gateway: Shard ID None has successfully RESUMED session c506966ff7c6a307316a6d0aa469a6aa.
[2025-08-02 03:39:44] [INFO    ] discord.gateway: Shard ID None has successfully RESUMED session c506966ff7c6a307316a6d0aa469a6aa.
[2025-08-02 03:57:11] [INFO    ] discord.gateway: Shard ID None has successfully RESUMED session c506966ff7c6a307316a6d0aa469a6aa.
[2025-08-02 04:50:41] [INFO    ] discord.gateway: Shard ID None has successfully RESUMED session c506966ff7c6a307316a6d0aa469a6aa.
[2025-08-02 07:45:08] [INFO    ] discord.gateway: Shard ID None has successfully RESUMED session c506966ff7c6a307316a6d0aa469a6aa.
[2025-08-02 09:58:18] [INFO    ] discord.gateway: Shard ID None has successfully RESUMED session c506966ff7c6a307316a6d0aa469a6aa.
[2025-08-02 11:54:29] [INFO    ] discord.gateway: Shard ID None has successfully RESUMED session c506966ff7c6a307316a6d0aa469a6aa.
[2025-08-02 15:04:31] [INFO    ] discord.gateway: Shard ID None has successfully RESUMED session c506966ff7c6a307316a6d0aa469a6aa.
[2025-08-02 17:13:03] [INFO    ] discord.gateway: Shard ID None has successfully RESUMED session c506966ff7c6a307316a6d0aa469a6aa.
[2025-08-02 20:35:51] [INFO    ] discord.gateway: Shard ID None has successfully RESUMED session c506966ff7c6a307316a6d0aa469a6aa.
[2025-08-02 21:55:53] [INFO    ] discord.gateway: Shard ID None has successfully RESUMED session c506966ff7c6a307316a6d0aa469a6aa.
[2025-08-03 01:11:57] [INFO    ] discord.gateway: Shard ID None has successfully RESUMED session c506966ff7c6a307316a6d0aa469a6aa.
[2025-08-03 02:08:55] [INFO    ] discord.gateway: Shard ID None has successfully RESUMED session c506966ff7c6a307316a6d0aa469a6aa.
[2025-08-03 02:29:19] [ERROR   ] discord.app_commands.tree: Ignoring exception in command 'bank_list'
Traceback (most recent call last):
  File "/root/Reymond/lib/discord/app_commands/commands.py", line 858, in _do_call
    return await self._callback(interaction, **params)  # type: ignore
           ^^^^^^^^^^^^^^^^^^^^^^^^^^^^^^^^^^^^^^^^^^^
  File "/root/Reymond/main.py", line 1022, in bank_list
    await interaction.response.send_message(embed=embed, ephemeral=True)
  File "/root/Reymond/lib/discord/interactions.py", line 1004, in send_message
    response = await adapter.create_interaction_response(
               ^^^^^^^^^^^^^^^^^^^^^^^^^^^^^^^^^^^^^^^^^^
  File "/root/Reymond/lib/discord/webhook/async_.py", line 224, in request
    raise NotFound(response, data)
discord.errors.NotFound: 404 Not Found (error code: 10062): Unknown interaction

The above exception was the direct cause of the following exception:

Traceback (most recent call last):
  File "/root/Reymond/lib/discord/app_commands/tree.py", line 1310, in _call
    await command._invoke_with_namespace(interaction, namespace)
  File "/root/Reymond/lib/discord/app_commands/commands.py", line 883, in _invoke_with_namespace
    return await self._do_call(interaction, transformed_values)
           ^^^^^^^^^^^^^^^^^^^^^^^^^^^^^^^^^^^^^^^^^^^^^^^^^^^^
  File "/root/Reymond/lib/discord/app_commands/commands.py", line 876, in _do_call
    raise CommandInvokeError(self, e) from e
discord.app_commands.errors.CommandInvokeError: Command 'bank_list' raised an exception: NotFound: 404 Not Found (error code: 10062): Unknown interaction
[2025-08-03 03:00:56] [INFO    ] discord.gateway: Shard ID None has successfully RESUMED session c506966ff7c6a307316a6d0aa469a6aa.
[2025-08-03 05:49:40] [INFO    ] discord.gateway: Shard ID None has successfully RESUMED session c506966ff7c6a307316a6d0aa469a6aa.
[2025-08-03 08:23:13] [INFO    ] discord.gateway: Shard ID None has successfully RESUMED session c506966ff7c6a307316a6d0aa469a6aa.
[2025-08-03 10:54:04] [ERROR   ] discord.client: Attempting a reconnect in 1.79s
Traceback (most recent call last):
  File "/usr/lib/python3.12/asyncio/tasks.py", line 520, in wait_for
    return await fut
           ^^^^^^^^^
  File "/root/Reymond/lib/discord/gateway.py", line 375, in from_client
    socket = await client.http.ws_connect(str(url))
             ^^^^^^^^^^^^^^^^^^^^^^^^^^^^^^^^^^^^^^
  File "/root/Reymond/lib/discord/http.py", line 554, in ws_connect
    return await self.__session.ws_connect(url, **kwargs)
           ^^^^^^^^^^^^^^^^^^^^^^^^^^^^^^^^^^^^^^^^^^^^^^
  File "/root/Reymond/lib/aiohttp/client.py", line 1048, in _ws_connect
    resp = await self.request(
           ^^^^^^^^^^^^^^^^^^^
  File "/root/Reymond/lib/aiohttp/client.py", line 760, in _request
    resp = await handler(req)
           ^^^^^^^^^^^^^^^^^^
  File "/root/Reymond/lib/aiohttp/client.py", line 715, in _connect_and_send_request
    conn = await self._connector.connect(
           ^^^^^^^^^^^^^^^^^^^^^^^^^^^^^^
  File "/root/Reymond/lib/aiohttp/connector.py", line 561, in connect
    proto = await self._create_connection(req, traces, timeout)
            ^^^^^^^^^^^^^^^^^^^^^^^^^^^^^^^^^^^^^^^^^^^^^^^^^^^
  File "/root/Reymond/lib/aiohttp/connector.py", line 1074, in _create_connection
    _, proto = await self._create_direct_connection(req, traces, timeout)
               ^^^^^^^^^^^^^^^^^^^^^^^^^^^^^^^^^^^^^^^^^^^^^^^^^^^^^^^^^^
  File "/root/Reymond/lib/aiohttp/connector.py", line 1394, in _create_direct_connection
    transp, proto = await self._wrap_create_connection(
                    ^^^^^^^^^^^^^^^^^^^^^^^^^^^^^^^^^^^
  File "/root/Reymond/lib/aiohttp/connector.py", line 1141, in _wrap_create_connection
    return await self._loop.create_connection(*args, **kwargs, sock=sock)
           ^^^^^^^^^^^^^^^^^^^^^^^^^^^^^^^^^^^^^^^^^^^^^^^^^^^^^^^^^^^^^^
  File "/usr/lib/python3.12/asyncio/base_events.py", line 1149, in create_connection
    transport, protocol = await self._create_connection_transport(
                          ^^^^^^^^^^^^^^^^^^^^^^^^^^^^^^^^^^^^^^^^
  File "/usr/lib/python3.12/asyncio/base_events.py", line 1182, in _create_connection_transport
    await waiter
asyncio.exceptions.CancelledError

The above exception was the direct cause of the following exception:

Traceback (most recent call last):
  File "/root/Reymond/lib/discord/client.py", line 701, in connect
    self.ws = await asyncio.wait_for(coro, timeout=60.0)
              ^^^^^^^^^^^^^^^^^^^^^^^^^^^^^^^^^^^^^^^^^^
  File "/usr/lib/python3.12/asyncio/tasks.py", line 519, in wait_for
    async with timeouts.timeout(timeout):
  File "/usr/lib/python3.12/asyncio/timeouts.py", line 115, in __aexit__
    raise TimeoutError from exc_val
TimeoutError
[2025-08-03 10:54:06] [INFO    ] discord.gateway: Shard ID None has successfully RESUMED session c506966ff7c6a307316a6d0aa469a6aa.
[2025-08-03 14:36:09] [INFO    ] discord.gateway: Shard ID None has successfully RESUMED session c506966ff7c6a307316a6d0aa469a6aa.
[2025-08-03 16:34:41] [INFO    ] discord.gateway: Shard ID None has successfully RESUMED session c506966ff7c6a307316a6d0aa469a6aa.
[2025-08-03 19:56:05] [INFO    ] discord.gateway: Shard ID None has successfully RESUMED session c506966ff7c6a307316a6d0aa469a6aa.
[2025-08-03 22:22:37] [INFO    ] discord.gateway: Shard ID None has successfully RESUMED session c506966ff7c6a307316a6d0aa469a6aa.
[2025-08-03 23:32:46] [INFO    ] discord.gateway: Shard ID None has successfully RESUMED session c506966ff7c6a307316a6d0aa469a6aa.
[2025-08-04 01:22:53] [INFO    ] discord.gateway: Shard ID None has successfully RESUMED session c506966ff7c6a307316a6d0aa469a6aa.
[2025-08-04 02:03:42] [INFO    ] discord.gateway: Shard ID None has successfully RESUMED session c506966ff7c6a307316a6d0aa469a6aa.
[2025-08-04 04:42:32] [INFO    ] discord.gateway: Shard ID None has successfully RESUMED session c506966ff7c6a307316a6d0aa469a6aa.
[2025-08-04 06:37:35] [INFO    ] discord.gateway: Shard ID None has successfully RESUMED session c506966ff7c6a307316a6d0aa469a6aa.
[2025-08-04 07:53:44] [INFO    ] discord.gateway: Shard ID None has successfully RESUMED session c506966ff7c6a307316a6d0aa469a6aa.
[2025-08-04 08:18:30] [INFO    ] discord.gateway: Shard ID None has successfully RESUMED session c506966ff7c6a307316a6d0aa469a6aa.
[2025-08-04 10:00:09] [INFO    ] discord.gateway: Shard ID None has successfully RESUMED session c506966ff7c6a307316a6d0aa469a6aa.
[2025-08-04 13:18:29] [INFO    ] discord.gateway: Shard ID None has successfully RESUMED session c506966ff7c6a307316a6d0aa469a6aa.
[2025-08-04 13:43:56] [INFO    ] discord.gateway: Shard ID None has successfully RESUMED session c506966ff7c6a307316a6d0aa469a6aa.
[2025-08-04 14:31:44] [INFO    ] discord.gateway: Shard ID None has successfully RESUMED session c506966ff7c6a307316a6d0aa469a6aa.
[2025-08-04 15:18:55] [INFO    ] discord.gateway: Shard ID None has successfully RESUMED session c506966ff7c6a307316a6d0aa469a6aa.
[2025-08-04 16:30:50] [INFO    ] discord.gateway: Shard ID None has successfully RESUMED session c506966ff7c6a307316a6d0aa469a6aa.
[2025-08-04 19:07:47] [INFO    ] discord.gateway: Shard ID None has successfully RESUMED session c506966ff7c6a307316a6d0aa469a6aa.
[2025-08-04 19:46:30] [ERROR   ] discord.client: Attempting a reconnect in 0.09s
Traceback (most recent call last):
  File "/usr/lib/python3.12/asyncio/tasks.py", line 520, in wait_for
    return await fut
           ^^^^^^^^^
  File "/root/Reymond/lib/discord/gateway.py", line 375, in from_client
    socket = await client.http.ws_connect(str(url))
             ^^^^^^^^^^^^^^^^^^^^^^^^^^^^^^^^^^^^^^
  File "/root/Reymond/lib/discord/http.py", line 554, in ws_connect
    return await self.__session.ws_connect(url, **kwargs)
           ^^^^^^^^^^^^^^^^^^^^^^^^^^^^^^^^^^^^^^^^^^^^^^
  File "/root/Reymond/lib/aiohttp/client.py", line 1048, in _ws_connect
    resp = await self.request(
           ^^^^^^^^^^^^^^^^^^^
  File "/root/Reymond/lib/aiohttp/client.py", line 760, in _request
    resp = await handler(req)
           ^^^^^^^^^^^^^^^^^^
  File "/root/Reymond/lib/aiohttp/client.py", line 715, in _connect_and_send_request
    conn = await self._connector.connect(
           ^^^^^^^^^^^^^^^^^^^^^^^^^^^^^^
  File "/root/Reymond/lib/aiohttp/connector.py", line 561, in connect
    proto = await self._create_connection(req, traces, timeout)
            ^^^^^^^^^^^^^^^^^^^^^^^^^^^^^^^^^^^^^^^^^^^^^^^^^^^
  File "/root/Reymond/lib/aiohttp/connector.py", line 1074, in _create_connection
    _, proto = await self._create_direct_connection(req, traces, timeout)
               ^^^^^^^^^^^^^^^^^^^^^^^^^^^^^^^^^^^^^^^^^^^^^^^^^^^^^^^^^^
  File "/root/Reymond/lib/aiohttp/connector.py", line 1394, in _create_direct_connection
    transp, proto = await self._wrap_create_connection(
                    ^^^^^^^^^^^^^^^^^^^^^^^^^^^^^^^^^^^
  File "/root/Reymond/lib/aiohttp/connector.py", line 1141, in _wrap_create_connection
    return await self._loop.create_connection(*args, **kwargs, sock=sock)
           ^^^^^^^^^^^^^^^^^^^^^^^^^^^^^^^^^^^^^^^^^^^^^^^^^^^^^^^^^^^^^^
  File "/usr/lib/python3.12/asyncio/base_events.py", line 1149, in create_connection
    transport, protocol = await self._create_connection_transport(
                          ^^^^^^^^^^^^^^^^^^^^^^^^^^^^^^^^^^^^^^^^
  File "/usr/lib/python3.12/asyncio/base_events.py", line 1182, in _create_connection_transport
    await waiter
asyncio.exceptions.CancelledError

The above exception was the direct cause of the following exception:

Traceback (most recent call last):
  File "/root/Reymond/lib/discord/client.py", line 701, in connect
    self.ws = await asyncio.wait_for(coro, timeout=60.0)
              ^^^^^^^^^^^^^^^^^^^^^^^^^^^^^^^^^^^^^^^^^^
  File "/usr/lib/python3.12/asyncio/tasks.py", line 519, in wait_for
    async with timeouts.timeout(timeout):
  File "/usr/lib/python3.12/asyncio/timeouts.py", line 115, in __aexit__
    raise TimeoutError from exc_val
TimeoutError
[2025-08-04 19:46:30] [INFO    ] discord.gateway: Shard ID None has successfully RESUMED session c506966ff7c6a307316a6d0aa469a6aa.
[2025-08-04 20:32:42] [INFO    ] discord.gateway: Shard ID None has successfully RESUMED session c506966ff7c6a307316a6d0aa469a6aa.
[2025-08-04 22:22:09] [INFO    ] discord.gateway: Shard ID None has successfully RESUMED session c506966ff7c6a307316a6d0aa469a6aa.
[2025-08-04 23:31:08] [INFO    ] discord.gateway: Shard ID None has successfully RESUMED session c506966ff7c6a307316a6d0aa469a6aa.
[2025-08-05 01:29:59] [INFO    ] discord.gateway: Shard ID None has successfully RESUMED session c506966ff7c6a307316a6d0aa469a6aa.
[2025-08-05 03:14:00] [INFO    ] discord.gateway: Shard ID None has successfully RESUMED session c506966ff7c6a307316a6d0aa469a6aa.
[2025-08-05 04:47:32] [INFO    ] discord.gateway: Shard ID None has successfully RESUMED session c506966ff7c6a307316a6d0aa469a6aa.
[2025-08-05 07:40:47] [INFO    ] discord.gateway: Shard ID None has successfully RESUMED session c506966ff7c6a307316a6d0aa469a6aa.
[2025-08-05 09:09:44] [INFO    ] discord.gateway: Shard ID None has successfully RESUMED session c506966ff7c6a307316a6d0aa469a6aa.
[2025-08-05 12:47:22] [INFO    ] discord.gateway: Shard ID None has successfully RESUMED session c506966ff7c6a307316a6d0aa469a6aa.
[2025-08-05 14:56:11] [INFO    ] discord.gateway: Shard ID None has successfully RESUMED session c506966ff7c6a307316a6d0aa469a6aa.
[2025-08-05 16:42:53] [INFO    ] discord.gateway: Shard ID None has successfully RESUMED session c506966ff7c6a307316a6d0aa469a6aa.
[2025-08-05 19:53:31] [INFO    ] discord.gateway: Shard ID None has successfully RESUMED session c506966ff7c6a307316a6d0aa469a6aa.
[2025-08-05 23:06:47] [INFO    ] discord.gateway: Shard ID None has successfully RESUMED session c506966ff7c6a307316a6d0aa469a6aa.
[2025-08-06 00:56:40] [INFO    ] discord.gateway: Shard ID None has successfully RESUMED session c506966ff7c6a307316a6d0aa469a6aa.
[2025-08-06 01:19:48] [INFO    ] discord.gateway: Shard ID None has successfully RESUMED session c506966ff7c6a307316a6d0aa469a6aa.
[2025-08-06 02:13:16] [INFO    ] discord.gateway: Shard ID None has successfully RESUMED session c506966ff7c6a307316a6d0aa469a6aa.
[2025-08-06 02:30:27] [INFO    ] discord.gateway: Shard ID None has successfully RESUMED session c506966ff7c6a307316a6d0aa469a6aa.
[2025-08-06 03:27:27] [INFO    ] discord.gateway: Shard ID None has successfully RESUMED session c506966ff7c6a307316a6d0aa469a6aa.
[2025-08-06 03:48:45] [INFO    ] discord.gateway: Shard ID None has successfully RESUMED session c506966ff7c6a307316a6d0aa469a6aa.
[2025-08-06 05:47:42] [INFO    ] discord.gateway: Shard ID None has successfully RESUMED session c506966ff7c6a307316a6d0aa469a6aa.
[2025-08-06 08:42:50] [INFO    ] discord.gateway: Shard ID None has successfully RESUMED session c506966ff7c6a307316a6d0aa469a6aa.
[2025-08-06 11:46:19] [INFO    ] discord.gateway: Shard ID None has successfully RESUMED session c506966ff7c6a307316a6d0aa469a6aa.
[2025-08-06 12:43:39] [INFO    ] discord.gateway: Shard ID None has successfully RESUMED session c506966ff7c6a307316a6d0aa469a6aa.
[2025-08-06 14:51:08] [INFO    ] discord.gateway: Shard ID None has successfully RESUMED session c506966ff7c6a307316a6d0aa469a6aa.
[2025-08-06 17:17:15] [INFO    ] discord.gateway: Shard ID None has successfully RESUMED session c506966ff7c6a307316a6d0aa469a6aa.
[2025-08-06 17:48:17] [INFO    ] discord.gateway: Shard ID None has successfully RESUMED session c506966ff7c6a307316a6d0aa469a6aa.
[2025-08-06 20:09:23] [INFO    ] discord.gateway: Shard ID None has successfully RESUMED session c506966ff7c6a307316a6d0aa469a6aa.
[2025-08-06 20:46:54] [INFO    ] discord.gateway: Shard ID None has successfully RESUMED session c506966ff7c6a307316a6d0aa469a6aa.
[2025-08-06 22:53:45] [INFO    ] discord.gateway: Shard ID None has successfully RESUMED session c506966ff7c6a307316a6d0aa469a6aa.
[2025-08-06 23:32:21] [INFO    ] discord.gateway: Shard ID None has successfully RESUMED session c506966ff7c6a307316a6d0aa469a6aa.
[2025-08-07 02:03:41] [INFO    ] discord.gateway: Shard ID None has successfully RESUMED session c506966ff7c6a307316a6d0aa469a6aa.
[2025-08-07 03:13:48] [INFO    ] discord.gateway: Shard ID None has successfully RESUMED session c506966ff7c6a307316a6d0aa469a6aa.
[2025-08-07 05:10:07] [INFO    ] discord.gateway: Shard ID None has successfully RESUMED session c506966ff7c6a307316a6d0aa469a6aa.
[2025-08-07 05:51:31] [INFO    ] discord.gateway: Shard ID None has successfully RESUMED session c506966ff7c6a307316a6d0aa469a6aa.
[2025-08-07 06:53:33] [INFO    ] discord.gateway: Shard ID None has successfully RESUMED session c506966ff7c6a307316a6d0aa469a6aa.
[2025-08-07 07:10:04] [INFO    ] discord.gateway: Shard ID None has successfully RESUMED session c506966ff7c6a307316a6d0aa469a6aa.
[2025-08-07 07:24:08] [ERROR   ] discord.client: Attempting a reconnect in 1.35s
Traceback (most recent call last):
  File "/usr/lib/python3.12/asyncio/tasks.py", line 520, in wait_for
    return await fut
           ^^^^^^^^^
  File "/root/Reymond/lib/discord/gateway.py", line 375, in from_client
    socket = await client.http.ws_connect(str(url))
             ^^^^^^^^^^^^^^^^^^^^^^^^^^^^^^^^^^^^^^
  File "/root/Reymond/lib/discord/http.py", line 554, in ws_connect
    return await self.__session.ws_connect(url, **kwargs)
           ^^^^^^^^^^^^^^^^^^^^^^^^^^^^^^^^^^^^^^^^^^^^^^
  File "/root/Reymond/lib/aiohttp/client.py", line 1048, in _ws_connect
    resp = await self.request(
           ^^^^^^^^^^^^^^^^^^^
  File "/root/Reymond/lib/aiohttp/client.py", line 760, in _request
    resp = await handler(req)
           ^^^^^^^^^^^^^^^^^^
  File "/root/Reymond/lib/aiohttp/client.py", line 715, in _connect_and_send_request
    conn = await self._connector.connect(
           ^^^^^^^^^^^^^^^^^^^^^^^^^^^^^^
  File "/root/Reymond/lib/aiohttp/connector.py", line 561, in connect
    proto = await self._create_connection(req, traces, timeout)
            ^^^^^^^^^^^^^^^^^^^^^^^^^^^^^^^^^^^^^^^^^^^^^^^^^^^
  File "/root/Reymond/lib/aiohttp/connector.py", line 1074, in _create_connection
    _, proto = await self._create_direct_connection(req, traces, timeout)
               ^^^^^^^^^^^^^^^^^^^^^^^^^^^^^^^^^^^^^^^^^^^^^^^^^^^^^^^^^^
  File "/root/Reymond/lib/aiohttp/connector.py", line 1394, in _create_direct_connection
    transp, proto = await self._wrap_create_connection(
                    ^^^^^^^^^^^^^^^^^^^^^^^^^^^^^^^^^^^
  File "/root/Reymond/lib/aiohttp/connector.py", line 1141, in _wrap_create_connection
    return await self._loop.create_connection(*args, **kwargs, sock=sock)
           ^^^^^^^^^^^^^^^^^^^^^^^^^^^^^^^^^^^^^^^^^^^^^^^^^^^^^^^^^^^^^^
  File "/usr/lib/python3.12/asyncio/base_events.py", line 1149, in create_connection
    transport, protocol = await self._create_connection_transport(
                          ^^^^^^^^^^^^^^^^^^^^^^^^^^^^^^^^^^^^^^^^
  File "/usr/lib/python3.12/asyncio/base_events.py", line 1182, in _create_connection_transport
    await waiter
asyncio.exceptions.CancelledError

The above exception was the direct cause of the following exception:

Traceback (most recent call last):
  File "/root/Reymond/lib/discord/client.py", line 701, in connect
    self.ws = await asyncio.wait_for(coro, timeout=60.0)
              ^^^^^^^^^^^^^^^^^^^^^^^^^^^^^^^^^^^^^^^^^^
  File "/usr/lib/python3.12/asyncio/tasks.py", line 519, in wait_for
    async with timeouts.timeout(timeout):
  File "/usr/lib/python3.12/asyncio/timeouts.py", line 115, in __aexit__
    raise TimeoutError from exc_val
TimeoutError
[2025-08-07 07:24:10] [INFO    ] discord.gateway: Shard ID None has successfully RESUMED session c506966ff7c6a307316a6d0aa469a6aa.
[2025-08-07 07:35:10] [INFO    ] discord.gateway: Shard ID None has successfully RESUMED session c506966ff7c6a307316a6d0aa469a6aa.
[2025-08-07 08:57:18] [INFO    ] discord.gateway: Shard ID None has successfully RESUMED session c506966ff7c6a307316a6d0aa469a6aa.
[2025-08-07 11:56:41] [INFO    ] discord.gateway: Shard ID None has successfully RESUMED session c506966ff7c6a307316a6d0aa469a6aa.
[2025-08-07 12:12:38] [INFO    ] discord.gateway: Shard ID None has successfully RESUMED session c506966ff7c6a307316a6d0aa469a6aa.
[2025-08-07 14:12:58] [INFO    ] discord.gateway: Shard ID None has successfully RESUMED session c506966ff7c6a307316a6d0aa469a6aa.
[2025-08-07 15:26:12] [INFO    ] discord.gateway: Shard ID None has successfully RESUMED session c506966ff7c6a307316a6d0aa469a6aa.
[2025-08-07 18:10:17] [INFO    ] discord.gateway: Shard ID None has successfully RESUMED session c506966ff7c6a307316a6d0aa469a6aa.
[2025-08-07 19:03:34] [INFO    ] discord.gateway: Shard ID None has successfully RESUMED session c506966ff7c6a307316a6d0aa469a6aa.
[2025-08-07 20:14:10] [INFO    ] discord.gateway: Shard ID None has successfully RESUMED session c506966ff7c6a307316a6d0aa469a6aa.
[2025-08-07 21:55:44] [INFO    ] discord.gateway: Shard ID None has successfully RESUMED session c506966ff7c6a307316a6d0aa469a6aa.
[2025-08-07 22:18:21] [INFO    ] discord.gateway: Shard ID None has successfully RESUMED session c506966ff7c6a307316a6d0aa469a6aa.
[2025-08-07 23:22:41] [INFO    ] discord.gateway: Shard ID None has successfully RESUMED session c506966ff7c6a307316a6d0aa469a6aa.
[2025-08-07 23:29:37] [INFO    ] discord.gateway: Shard ID None has successfully RESUMED session c506966ff7c6a307316a6d0aa469a6aa.
[2025-08-08 03:19:18] [INFO    ] discord.gateway: Shard ID None has successfully RESUMED session c506966ff7c6a307316a6d0aa469a6aa.
[2025-08-08 03:28:15] [INFO    ] discord.gateway: Shard ID None has successfully RESUMED session c506966ff7c6a307316a6d0aa469a6aa.
[2025-08-08 06:22:32] [INFO    ] discord.gateway: Shard ID None has successfully RESUMED session c506966ff7c6a307316a6d0aa469a6aa.
[2025-08-08 07:37:50] [INFO    ] discord.gateway: Shard ID None has successfully RESUMED session c506966ff7c6a307316a6d0aa469a6aa.
[2025-08-08 11:15:06] [INFO    ] discord.gateway: Shard ID None has successfully RESUMED session c506966ff7c6a307316a6d0aa469a6aa.
[2025-08-08 13:09:02] [INFO    ] discord.gateway: Shard ID None has successfully RESUMED session c506966ff7c6a307316a6d0aa469a6aa.
[2025-08-08 16:29:15] [INFO    ] discord.gateway: Shard ID None has successfully RESUMED session c506966ff7c6a307316a6d0aa469a6aa.
[2025-08-08 19:59:51] [INFO    ] discord.gateway: Shard ID None has successfully RESUMED session c506966ff7c6a307316a6d0aa469a6aa.
[2025-08-08 20:52:00] [INFO    ] discord.gateway: Shard ID None has successfully RESUMED session c506966ff7c6a307316a6d0aa469a6aa.
[2025-08-08 23:24:58] [INFO    ] discord.gateway: Shard ID None has successfully RESUMED session c506966ff7c6a307316a6d0aa469a6aa.
[2025-08-09 00:09:39] [INFO    ] discord.gateway: Shard ID None has successfully RESUMED session c506966ff7c6a307316a6d0aa469a6aa.
[2025-08-09 00:59:57] [INFO    ] discord.gateway: Shard ID None has successfully RESUMED session c506966ff7c6a307316a6d0aa469a6aa.
[2025-08-09 02:42:09] [INFO    ] discord.gateway: Shard ID None has successfully RESUMED session c506966ff7c6a307316a6d0aa469a6aa.
[2025-08-09 03:34:01] [INFO    ] discord.gateway: Shard ID None has successfully RESUMED session c506966ff7c6a307316a6d0aa469a6aa.
[2025-08-09 03:50:59] [INFO    ] discord.gateway: Shard ID None has successfully RESUMED session c506966ff7c6a307316a6d0aa469a6aa.
[2025-08-09 06:01:06] [INFO    ] discord.gateway: Shard ID None has successfully RESUMED session c506966ff7c6a307316a6d0aa469a6aa.
[2025-08-11 16:14:36] [INFO    ] discord.client: logging in using static token
[2025-08-11 16:14:37] [INFO    ] discord.gateway: Shard ID None has connected to Gateway (Session ID: 73d87df4f4179668deff26c3ee9df942).
[2025-08-11 16:16:55] [ERROR   ] discord.app_commands.tree: Ignoring exception in command 'echo'
Traceback (most recent call last):
  File "/root/Reymond/lib/discord/app_commands/commands.py", line 858, in _do_call
    return await self._callback(interaction, **params)  # type: ignore
           ^^^^^^^^^^^^^^^^^^^^^^^^^^^^^^^^^^^^^^^^^^^
  File "/root/Reymond/main.py", line 65, in echo
    await interaction.response.send_message("Message sent!", ephemeral=True)
  File "/root/Reymond/lib/discord/interactions.py", line 1004, in send_message
    response = await adapter.create_interaction_response(
               ^^^^^^^^^^^^^^^^^^^^^^^^^^^^^^^^^^^^^^^^^^
  File "/root/Reymond/lib/discord/webhook/async_.py", line 224, in request
    raise NotFound(response, data)
discord.errors.NotFound: 404 Not Found (error code: 10062): Unknown interaction

The above exception was the direct cause of the following exception:

Traceback (most recent call last):
  File "/root/Reymond/lib/discord/app_commands/tree.py", line 1310, in _call
    await command._invoke_with_namespace(interaction, namespace)
  File "/root/Reymond/lib/discord/app_commands/commands.py", line 883, in _invoke_with_namespace
    return await self._do_call(interaction, transformed_values)
           ^^^^^^^^^^^^^^^^^^^^^^^^^^^^^^^^^^^^^^^^^^^^^^^^^^^^
  File "/root/Reymond/lib/discord/app_commands/commands.py", line 876, in _do_call
    raise CommandInvokeError(self, e) from e
discord.app_commands.errors.CommandInvokeError: Command 'echo' raised an exception: NotFound: 404 Not Found (error code: 10062): Unknown interaction
[2025-08-11 16:50:57] [INFO    ] discord.gateway: Shard ID None has successfully RESUMED session 73d87df4f4179668deff26c3ee9df942.
[2025-08-11 17:51:22] [INFO    ] discord.gateway: Shard ID None has successfully RESUMED session 73d87df4f4179668deff26c3ee9df942.
[2025-08-11 21:00:26] [INFO    ] discord.gateway: Shard ID None has successfully RESUMED session 73d87df4f4179668deff26c3ee9df942.
[2025-08-11 23:34:32] [INFO    ] discord.gateway: Shard ID None has successfully RESUMED session 73d87df4f4179668deff26c3ee9df942.
[2025-08-12 02:20:20] [INFO    ] discord.gateway: Shard ID None has successfully RESUMED session 73d87df4f4179668deff26c3ee9df942.
[2025-08-12 06:09:34] [INFO    ] discord.gateway: Shard ID None has successfully RESUMED session 73d87df4f4179668deff26c3ee9df942.
[2025-08-12 09:45:35] [INFO    ] discord.gateway: Shard ID None has successfully RESUMED session 73d87df4f4179668deff26c3ee9df942.
[2025-08-12 11:04:23] [INFO    ] discord.gateway: Shard ID None has successfully RESUMED session 73d87df4f4179668deff26c3ee9df942.
[2025-08-12 11:29:48] [INFO    ] discord.gateway: Shard ID None has successfully RESUMED session 73d87df4f4179668deff26c3ee9df942.
[2025-08-12 11:33:11] [INFO    ] discord.gateway: Shard ID None has successfully RESUMED session 73d87df4f4179668deff26c3ee9df942.
[2025-08-12 13:25:30] [INFO    ] discord.gateway: Shard ID None has successfully RESUMED session 73d87df4f4179668deff26c3ee9df942.
[2025-08-12 16:48:17] [INFO    ] discord.gateway: Shard ID None has successfully RESUMED session 73d87df4f4179668deff26c3ee9df942.
[2025-08-12 20:25:29] [INFO    ] discord.gateway: Shard ID None has successfully RESUMED session 73d87df4f4179668deff26c3ee9df942.
[2025-08-12 21:17:16] [INFO    ] discord.gateway: Shard ID None has successfully RESUMED session 73d87df4f4179668deff26c3ee9df942.
[2025-08-13 00:58:23] [INFO    ] discord.gateway: Shard ID None has successfully RESUMED session 73d87df4f4179668deff26c3ee9df942.
[2025-08-13 02:01:35] [INFO    ] discord.gateway: Shard ID None has successfully RESUMED session 73d87df4f4179668deff26c3ee9df942.
[2025-08-13 02:54:00] [INFO    ] discord.gateway: Shard ID None has successfully RESUMED session 73d87df4f4179668deff26c3ee9df942.
[2025-08-13 05:30:23] [INFO    ] discord.gateway: Shard ID None has successfully RESUMED session 73d87df4f4179668deff26c3ee9df942.
[2025-08-13 07:58:44] [INFO    ] discord.gateway: Shard ID None has successfully RESUMED session 73d87df4f4179668deff26c3ee9df942.
[2025-08-13 09:53:03] [INFO    ] discord.gateway: Shard ID None has successfully RESUMED session 73d87df4f4179668deff26c3ee9df942.
[2025-08-13 10:58:22] [INFO    ] discord.gateway: Shard ID None has successfully RESUMED session 73d87df4f4179668deff26c3ee9df942.
[2025-08-13 12:00:48] [INFO    ] discord.gateway: Shard ID None has successfully RESUMED session 73d87df4f4179668deff26c3ee9df942.
[2025-08-13 13:41:11] [INFO    ] discord.gateway: Shard ID None has successfully RESUMED session 73d87df4f4179668deff26c3ee9df942.
[2025-08-13 14:05:56] [INFO    ] discord.gateway: Shard ID None has successfully RESUMED session 73d87df4f4179668deff26c3ee9df942.
[2025-08-13 14:59:10] [INFO    ] discord.gateway: Shard ID None has successfully RESUMED session 73d87df4f4179668deff26c3ee9df942.
[2025-08-13 16:10:53] [INFO    ] discord.gateway: Shard ID None has successfully RESUMED session 73d87df4f4179668deff26c3ee9df942.
[2025-08-13 16:55:50] [ERROR   ] discord.client: Attempting a reconnect in 1.33s
Traceback (most recent call last):
  File "/usr/lib/python3.12/asyncio/tasks.py", line 520, in wait_for
    return await fut
           ^^^^^^^^^
  File "/root/Reymond/lib/discord/gateway.py", line 375, in from_client
    socket = await client.http.ws_connect(str(url))
             ^^^^^^^^^^^^^^^^^^^^^^^^^^^^^^^^^^^^^^
  File "/root/Reymond/lib/discord/http.py", line 554, in ws_connect
    return await self.__session.ws_connect(url, **kwargs)
           ^^^^^^^^^^^^^^^^^^^^^^^^^^^^^^^^^^^^^^^^^^^^^^
  File "/root/Reymond/lib/aiohttp/client.py", line 1048, in _ws_connect
    resp = await self.request(
           ^^^^^^^^^^^^^^^^^^^
  File "/root/Reymond/lib/aiohttp/client.py", line 760, in _request
    resp = await handler(req)
           ^^^^^^^^^^^^^^^^^^
  File "/root/Reymond/lib/aiohttp/client.py", line 715, in _connect_and_send_request
    conn = await self._connector.connect(
           ^^^^^^^^^^^^^^^^^^^^^^^^^^^^^^
  File "/root/Reymond/lib/aiohttp/connector.py", line 561, in connect
    proto = await self._create_connection(req, traces, timeout)
            ^^^^^^^^^^^^^^^^^^^^^^^^^^^^^^^^^^^^^^^^^^^^^^^^^^^
  File "/root/Reymond/lib/aiohttp/connector.py", line 1074, in _create_connection
    _, proto = await self._create_direct_connection(req, traces, timeout)
               ^^^^^^^^^^^^^^^^^^^^^^^^^^^^^^^^^^^^^^^^^^^^^^^^^^^^^^^^^^
  File "/root/Reymond/lib/aiohttp/connector.py", line 1394, in _create_direct_connection
    transp, proto = await self._wrap_create_connection(
                    ^^^^^^^^^^^^^^^^^^^^^^^^^^^^^^^^^^^
  File "/root/Reymond/lib/aiohttp/connector.py", line 1141, in _wrap_create_connection
    return await self._loop.create_connection(*args, **kwargs, sock=sock)
           ^^^^^^^^^^^^^^^^^^^^^^^^^^^^^^^^^^^^^^^^^^^^^^^^^^^^^^^^^^^^^^
  File "/usr/lib/python3.12/asyncio/base_events.py", line 1149, in create_connection
    transport, protocol = await self._create_connection_transport(
                          ^^^^^^^^^^^^^^^^^^^^^^^^^^^^^^^^^^^^^^^^
  File "/usr/lib/python3.12/asyncio/base_events.py", line 1182, in _create_connection_transport
    await waiter
asyncio.exceptions.CancelledError

The above exception was the direct cause of the following exception:

Traceback (most recent call last):
  File "/root/Reymond/lib/discord/client.py", line 701, in connect
    self.ws = await asyncio.wait_for(coro, timeout=60.0)
              ^^^^^^^^^^^^^^^^^^^^^^^^^^^^^^^^^^^^^^^^^^
  File "/usr/lib/python3.12/asyncio/tasks.py", line 519, in wait_for
    async with timeouts.timeout(timeout):
  File "/usr/lib/python3.12/asyncio/timeouts.py", line 115, in __aexit__
    raise TimeoutError from exc_val
TimeoutError
[2025-08-13 16:55:52] [INFO    ] discord.gateway: Shard ID None has successfully RESUMED session 73d87df4f4179668deff26c3ee9df942.
[2025-08-13 17:38:06] [INFO    ] discord.gateway: Shard ID None has successfully RESUMED session 73d87df4f4179668deff26c3ee9df942.
[2025-08-13 19:37:47] [INFO    ] discord.gateway: Shard ID None has successfully RESUMED session 73d87df4f4179668deff26c3ee9df942.
[2025-08-13 21:43:12] [INFO    ] discord.gateway: Shard ID None has successfully RESUMED session 73d87df4f4179668deff26c3ee9df942.
[2025-08-13 21:58:25] [INFO    ] discord.gateway: Shard ID None has successfully RESUMED session 73d87df4f4179668deff26c3ee9df942.
[2025-08-14 00:09:50] [INFO    ] discord.gateway: Shard ID None has successfully RESUMED session 73d87df4f4179668deff26c3ee9df942.
[2025-08-14 01:48:32] [INFO    ] discord.gateway: Shard ID None has successfully RESUMED session 73d87df4f4179668deff26c3ee9df942.
[2025-08-14 03:06:38] [ERROR   ] discord.client: Attempting a reconnect in 0.65s
Traceback (most recent call last):
  File "/usr/lib/python3.12/asyncio/tasks.py", line 520, in wait_for
    return await fut
           ^^^^^^^^^
  File "/root/Reymond/lib/discord/gateway.py", line 375, in from_client
    socket = await client.http.ws_connect(str(url))
             ^^^^^^^^^^^^^^^^^^^^^^^^^^^^^^^^^^^^^^
  File "/root/Reymond/lib/discord/http.py", line 554, in ws_connect
    return await self.__session.ws_connect(url, **kwargs)
           ^^^^^^^^^^^^^^^^^^^^^^^^^^^^^^^^^^^^^^^^^^^^^^
  File "/root/Reymond/lib/aiohttp/client.py", line 1048, in _ws_connect
    resp = await self.request(
           ^^^^^^^^^^^^^^^^^^^
  File "/root/Reymond/lib/aiohttp/client.py", line 760, in _request
    resp = await handler(req)
           ^^^^^^^^^^^^^^^^^^
  File "/root/Reymond/lib/aiohttp/client.py", line 715, in _connect_and_send_request
    conn = await self._connector.connect(
           ^^^^^^^^^^^^^^^^^^^^^^^^^^^^^^
  File "/root/Reymond/lib/aiohttp/connector.py", line 561, in connect
    proto = await self._create_connection(req, traces, timeout)
            ^^^^^^^^^^^^^^^^^^^^^^^^^^^^^^^^^^^^^^^^^^^^^^^^^^^
  File "/root/Reymond/lib/aiohttp/connector.py", line 1074, in _create_connection
    _, proto = await self._create_direct_connection(req, traces, timeout)
               ^^^^^^^^^^^^^^^^^^^^^^^^^^^^^^^^^^^^^^^^^^^^^^^^^^^^^^^^^^
  File "/root/Reymond/lib/aiohttp/connector.py", line 1394, in _create_direct_connection
    transp, proto = await self._wrap_create_connection(
                    ^^^^^^^^^^^^^^^^^^^^^^^^^^^^^^^^^^^
  File "/root/Reymond/lib/aiohttp/connector.py", line 1141, in _wrap_create_connection
    return await self._loop.create_connection(*args, **kwargs, sock=sock)
           ^^^^^^^^^^^^^^^^^^^^^^^^^^^^^^^^^^^^^^^^^^^^^^^^^^^^^^^^^^^^^^
  File "/usr/lib/python3.12/asyncio/base_events.py", line 1149, in create_connection
    transport, protocol = await self._create_connection_transport(
                          ^^^^^^^^^^^^^^^^^^^^^^^^^^^^^^^^^^^^^^^^
  File "/usr/lib/python3.12/asyncio/base_events.py", line 1182, in _create_connection_transport
    await waiter
asyncio.exceptions.CancelledError

The above exception was the direct cause of the following exception:

Traceback (most recent call last):
  File "/root/Reymond/lib/discord/client.py", line 701, in connect
    self.ws = await asyncio.wait_for(coro, timeout=60.0)
              ^^^^^^^^^^^^^^^^^^^^^^^^^^^^^^^^^^^^^^^^^^
  File "/usr/lib/python3.12/asyncio/tasks.py", line 519, in wait_for
    async with timeouts.timeout(timeout):
  File "/usr/lib/python3.12/asyncio/timeouts.py", line 115, in __aexit__
    raise TimeoutError from exc_val
TimeoutError
[2025-08-14 03:06:39] [INFO    ] discord.gateway: Shard ID None has successfully RESUMED session 73d87df4f4179668deff26c3ee9df942.
[2025-08-14 06:53:04] [ERROR   ] discord.client: Attempting a reconnect in 0.53s
Traceback (most recent call last):
  File "/usr/lib/python3.12/asyncio/tasks.py", line 520, in wait_for
    return await fut
           ^^^^^^^^^
  File "/root/Reymond/lib/discord/gateway.py", line 375, in from_client
    socket = await client.http.ws_connect(str(url))
             ^^^^^^^^^^^^^^^^^^^^^^^^^^^^^^^^^^^^^^
  File "/root/Reymond/lib/discord/http.py", line 554, in ws_connect
    return await self.__session.ws_connect(url, **kwargs)
           ^^^^^^^^^^^^^^^^^^^^^^^^^^^^^^^^^^^^^^^^^^^^^^
  File "/root/Reymond/lib/aiohttp/client.py", line 1048, in _ws_connect
    resp = await self.request(
           ^^^^^^^^^^^^^^^^^^^
  File "/root/Reymond/lib/aiohttp/client.py", line 760, in _request
    resp = await handler(req)
           ^^^^^^^^^^^^^^^^^^
  File "/root/Reymond/lib/aiohttp/client.py", line 715, in _connect_and_send_request
    conn = await self._connector.connect(
           ^^^^^^^^^^^^^^^^^^^^^^^^^^^^^^
  File "/root/Reymond/lib/aiohttp/connector.py", line 561, in connect
    proto = await self._create_connection(req, traces, timeout)
            ^^^^^^^^^^^^^^^^^^^^^^^^^^^^^^^^^^^^^^^^^^^^^^^^^^^
  File "/root/Reymond/lib/aiohttp/connector.py", line 1074, in _create_connection
    _, proto = await self._create_direct_connection(req, traces, timeout)
               ^^^^^^^^^^^^^^^^^^^^^^^^^^^^^^^^^^^^^^^^^^^^^^^^^^^^^^^^^^
  File "/root/Reymond/lib/aiohttp/connector.py", line 1394, in _create_direct_connection
    transp, proto = await self._wrap_create_connection(
                    ^^^^^^^^^^^^^^^^^^^^^^^^^^^^^^^^^^^
  File "/root/Reymond/lib/aiohttp/connector.py", line 1141, in _wrap_create_connection
    return await self._loop.create_connection(*args, **kwargs, sock=sock)
           ^^^^^^^^^^^^^^^^^^^^^^^^^^^^^^^^^^^^^^^^^^^^^^^^^^^^^^^^^^^^^^
  File "/usr/lib/python3.12/asyncio/base_events.py", line 1149, in create_connection
    transport, protocol = await self._create_connection_transport(
                          ^^^^^^^^^^^^^^^^^^^^^^^^^^^^^^^^^^^^^^^^
  File "/usr/lib/python3.12/asyncio/base_events.py", line 1182, in _create_connection_transport
    await waiter
asyncio.exceptions.CancelledError

The above exception was the direct cause of the following exception:

Traceback (most recent call last):
  File "/root/Reymond/lib/discord/client.py", line 701, in connect
    self.ws = await asyncio.wait_for(coro, timeout=60.0)
              ^^^^^^^^^^^^^^^^^^^^^^^^^^^^^^^^^^^^^^^^^^
  File "/usr/lib/python3.12/asyncio/tasks.py", line 519, in wait_for
    async with timeouts.timeout(timeout):
  File "/usr/lib/python3.12/asyncio/timeouts.py", line 115, in __aexit__
    raise TimeoutError from exc_val
TimeoutError
[2025-08-14 06:53:36] [INFO    ] discord.gateway: Shard ID None session has been invalidated.
[2025-08-14 06:53:41] [INFO    ] discord.gateway: Shard ID None has connected to Gateway (Session ID: 315eddd5e27dd5856d54f659118c0ec0).
[2025-08-14 07:49:01] [INFO    ] discord.gateway: Shard ID None has successfully RESUMED session 315eddd5e27dd5856d54f659118c0ec0.
[2025-08-14 09:38:59] [INFO    ] discord.gateway: Shard ID None has successfully RESUMED session 315eddd5e27dd5856d54f659118c0ec0.
[2025-08-14 12:32:19] [INFO    ] discord.gateway: Shard ID None has successfully RESUMED session 315eddd5e27dd5856d54f659118c0ec0.
[2025-08-14 12:35:41] [INFO    ] discord.gateway: Shard ID None has successfully RESUMED session 315eddd5e27dd5856d54f659118c0ec0.
[2025-08-14 12:39:10] [INFO    ] discord.gateway: Shard ID None has successfully RESUMED session 315eddd5e27dd5856d54f659118c0ec0.
[2025-08-14 15:42:26] [INFO    ] discord.gateway: Shard ID None has successfully RESUMED session 315eddd5e27dd5856d54f659118c0ec0.
